Workbook
Name B_KQKT: TTDN!$AR$41:$AS$50
Name Bang_CDSPS: CDSPS!$C$15:$J$434
Name Bang_CDSPSNT: CDSPS_NT!$C$15:$J$432
Name BangKe_BR: TTDN!$AZ$1:$BJ$16
Name BangKe_MV: TTDN!$AZ$19:$BK$34
Name BangVat: TTDN!$CX$3:$DJ$11
Name BR_1: BR!$A$7
Name BR_KT_1: BR!$T$7
Name BR_THop: BR!$Z$8:$AA$19
Name CDSPS_1: CDSPS!$C$14
Name CDSPS_CKC: CDSPS!$J$15:$J$433
Name CDSPS_CKC59: CDSPS!$J$364:$J$433
Name CDSPS_CKN: CDSPS!$I$15:$I$433
Name CDSPS_CKN59: CDSPS!$I$364:$I$433
Name CDSPS_DKC: CDSPS!$F$15:$F$433
Name CDSPS_DKN: CDSPS!$E$15:$E$433
Name CDSPS_N111: CDSPS!$E$16
Name CDSPS_NT_1: CDSPS_NT!$C$14
Name CDSPS_NT_TC: CDSPS_NT!$D$433
Name CDSPS_PSC: CDSPS!$H$15:$H$433
Name CDSPS_PSN: CDSPS!$G$15:$G$433
Name CDSPS_TC: CDSPS!$D$435
Name CDSPS_TK: CDSPS!$C$15:$C$433
Name CDSPSNT_CKC: TTDN!$AN$37
Name CDSPSNT_CKN: TTDN!$AN$36
Name CDSPSNT_DKC: TTDN!$AN$33
Name CDSPSNT_DKN: TTDN!$AN$32
Name CDSPSNT_PSC: TTDN!$AN$35
Name CDSPSNT_PSN: TTDN!$AN$34
Name CDSPSNT_TK: TTDN!$AN$31
Name CN_CongPS: CN_CTiet!$C$21
Name CN_DongD: CN_CTiet!$C$16
Name CNPThu_1: SDDK_CN!$B$7
Name CNPThu_KT1: SDDK_CN!$G$7
Name CNPTra_1: SDDK_CN!$L$7
Name CNPTra_KT1: SDDK_CN!$Q$7
Name CNTH_1: CN_TH!$B$12
Name CNTH_TC: CN_TH!$C$15
Name DATA_CT: DATA_HDDT!$AI$1:$AS$150
Name DATA_HD: DATA_HDDT!$L$1:$AG$150
Name DATA_NM: DATA_HDDT!$A$1:$J$150
Name DC3738_1: DC_3738!$A$5
Name DC3738_TuDongHD: DC_3738!$L$2
Name DCQT_VatQ: GV!$AA$8:$AD$11
Name DCQT_VatT: GV!$U$8:$X$19
Name DCT_Ban: LuuY!$H$4
Name DCT_Mua: LuuY!$H$22
Name DK_C33311: CDSPS_NT!$J$287
Name DK_N133: CDSPS_NT!$I$129
Name DK_N33311: CDSPS_NT!$I$287
Name DK_N4212: CDSPS_NT!$I$361
Name GPAccTT99: Main!$D$1
Name GTGT_014B: GTGT!$V$24:$V$36
Name GTGT_32b: GTGT!$K$19
Name GTGT_34a: GTGT!$L$19
Name GTGT_DCVatQ: GTGT!$O$7:$P$10
Name GTGT_DCVatT: GTGT!$K$7:$L$18
Name GTGT_DK: GTGT!$H$23
Name GTGT_PBThue: GTGT!$O$24:$O$34
Name GTrinh_152: Giai_Trinh!$B$5

Sheet Main
A1: 29 | B1: 46294.564 | D1: PHẦN MỀM KẾ TOÁN GPAcc | Theo Thông tư 99/2025/TT-BTC | P1: ="Kỳ kế toán · Năm "&$A$3 -> Kỳ kế toán · Năm 2026
A2: 9
A3: 2026
A4: 19
A5: 8
A6: BÍNH NGỌ | D6: GPAcc
A7: Ất Mùi | M7: ="THÁNG "&TEXT($A$2,"00")&" · "&$A$3 -> THÁNG 09 · 2026
M9: =$A$1 -> 29
D12: Phần mềm kế toán doanh nghiệp trên Microsoft Excel
N23: =CHOOSE(WEEKDAY($B$1),"CHỦ NHẬT","THỨ HAI","THỨ BA","THỨ TƯ","THỨ NĂM","THỨ SÁU","THỨ BẢY") -> THỨ BA
D27: =IF(LEN(KB_CTy)=0,"",KB_CTy)
D28: ="Mã số thuế: "&IF(LEN(KB_MST)=0,"",KB_MST) -> Mã số thuế: | M28: ÂM LỊCH
D29: ="Địa chỉ: "&IF(LEN(KB_DC)=0,"",KB_DC) -> Địa chỉ: | M29: =$A$4&" tháng "&$A$5 -> 19 tháng 8 | Q29: ="Năm "&$A$6 -> Năm BÍNH NGỌ

Sheet VA_BOCUC
A1: Mã việc | B1: Loại | C1: Sheet | D1: Vùng | E1: Giá trị | F1: Tham số | G1: Điều kiện | H1: Ghi chú | I1: Tắt | K1: CÁCH DÙNG BẢNG NÀY
A2: VD_01 | B2: CONGTHUC | C2: PBKH | D2: I4 | E2: =SUBTOTAL(9,I9:I2000) | G2: KHAC | H2: ví dụ: đặt lại công thức cộng tổng | I2: x
A3: VD_02 | B3: DINHDANG | C3: PBKH | D3: I4 | F3: so=#,##0;font=Segoe UI;co=10;dam=1;chu=#174F8C;canh=phai | G3: KHAC | H3: ví dụ: định dạng ô vừa đặt | I3: x | K3: Mỗi DÒNG là một việc sửa bố cục. Sửa bảng này trong gói MauBieu.xlsx rồi phát hành
A4: VD_03 | B4: NUT | C4: RapMa | E4: RapMa_Auto | F4: ten=NutVD_Thu;chu=Thử Nút;l=700;t=2;w=110;h=22;nen=#FFFFFF;vien=#2F6EAD;chumau=#1F2937 | G4: KHAC | H4: ví dụ: thêm một nút lệnh | I4: x | K4: PhatHanh.ps1 -Ver <yymmdd> -TangSchema → khách bấm «Cập Nhật Mẫu Biểu» rồi
A5: VA260921_11 | B5: CONGTHUC | C5: KQKD | D5: J16 | E5: =IFERROR(+H16/H13,"") | G5: KHAC | H5: Boc IFERROR: file chua co so lieu thi ty le chia ra #DIV/0! | K5: «Nâng Cấp Bố Cục» là xong. KHÔNG cần phát hành vbaProject.bin, không cần viết code.
A6: VA260921_12 | B6: CONGTHUC | C6: KQKD | D6: K16 | E6: =IFERROR(+I16/I13,"") | G6: KHAC | H6: Boc IFERROR: file chua co so lieu thi ty le chia ra #DIV/0!
A7: VA260921_13 | B7: CONGTHUC | C7: KQKD | D7: J28 | E7: =IFERROR(H28/H15,"") | G7: KHAC | H7: Boc IFERROR: file chua co so lieu thi ty le chia ra #DIV/0! | K7: CỘT B — Loại việc:
A8: VA260921_14 | B8: CONGTHUC | C8: KQKD | D8: K28 | E8: =IFERROR(I28/I15,"") | G8: KHAC | H8: Boc IFERROR: file chua co so lieu thi ty le chia ra #DIV/0! | K8: CONGTHUC đặt công thức cho ô/vùng (cột E là công thức, ví dụ =SUBTOTAL(9,I9:I2000))
A9: VA26093001_01 | B9: CONGTHUC | C9: TMinh | D9: M214 | E9: =+VLOOKUP(M210,Bang_CDSPS,5,0) | G9: KHAC | H9: TM muc 9: TSCD huu hinh mua trong nam = PS No TK 211x | K9: GIATRI đặt giá trị / chữ cho ô/vùng
A10: VA26093001_02 | B10: CONGTHUC | C10: TMinh | D10: Q214 | E10: =+VLOOKUP(Q210,Bang_CDSPS,5,0) | G10: KHAC | H10: TM muc 9: TSCD huu hinh mua trong nam = PS No TK 211x | K10: DINHDANG định dạng ô/vùng (tham số ở cột F)
A11: VA26093001_03 | B11: CONGTHUC | C11: TMinh | D11: U214 | E11: =+VLOOKUP(U210,Bang_CDSPS,5,0) | G11: KHAC | H11: TM muc 9: TSCD huu hinh mua trong nam = PS No TK 211x | K11: NAME thêm / trỏ lại Name toàn cục (cột D = tên Name, cột E = =Sheet!$A$1)
A12: VA26093001_04 | B12: CONGTHUC | C12: TMinh | D12: Y214 | E12: =+VLOOKUP(Y210,Bang_CDSPS,5,0) | G12: KHAC | H12: TM muc 9: TSCD huu hinh mua trong nam = PS No TK 211x | K12: VALIDATION danh sách chọn (cột E: các mục cách nhau dấu | )
A13: VA26093001_05 | B13: CONGTHUC | C13: TMinh | D13: AC214 | E13: =+VLOOKUP(AC210,Bang_CDSPS,5,0) | G13: KHAC | H13: TM muc 9: TSCD huu hinh mua trong nam = PS No TK 211x | K13: NUT thêm nút lệnh (cột E = tên macro, cột F: ten= chu= l= t= w= h= nen= vien= chumau=)
A14: VA26093001_06 | B14: CONGTHUC | C14: TMinh | D14: M222 | E14: =+SUMIF(Bang_TSCD!$B$16:$B$5000,M210,Bang_TSCD!$R$16:$R$5000) | G14: KHAC | H14: TM muc 9: hao mon luy ke dau nam lay tu Bang_TSCD | K14: HIENSHEET cột E = hien | an | anhan
A15: VA26093001_07 | B15: CONGTHUC | C15: TMinh | D15: Q222 | E15: =+SUMIF(Bang_TSCD!$B$16:$B$5000,Q210,Bang_TSCD!$R$16:$R$5000) | G15: KHAC | H15: TM muc 9: hao mon luy ke dau nam lay tu Bang_TSCD | K15: VUNGIN cột D = vùng in
A16: VA26093001_08 | B16: CONGTHUC | C16: TMinh | D16: U222 | E16: =+SUMIF(Bang_TSCD!$B$16:$B$5000,U210,Bang_TSCD!$R$16:$R$5000) | G16: KHAC | H16: TM muc 9: hao mon luy ke dau nam lay tu Bang_TSCD
A17: VA26093001_09 | B17: CONGTHUC | C17: TMinh | D17: Y222 | E17: =+SUMIF(Bang_TSCD!$B$16:$B$5000,Y210,Bang_TSCD!$R$16:$R$5000) | G17: KHAC | H17: TM muc 9: hao mon luy ke dau nam lay tu Bang_TSCD | K17: CỘT F — tham số DINHDANG (chỉ ghi cái cần đổi, cách nhau dấu chấm phẩy):
A18: VA26093001_10 | B18: CONGTHUC | C18: TMinh | D18: AC222 | E18: =+SUMIF(Bang_TSCD!$B$16:$B$5000,AC210,Bang_TSCD!$R$16:$R$5000) | G18: KHAC | H18: TM muc 9: hao mon luy ke dau nam lay tu Bang_TSCD | K18: so=#,##0 font=Segoe UI co=10 dam=1 nghieng=0 chu=#174F8C nen=#DCEBF7
A19: VA26093001_11 | B19: CONGTHUC | C19: TMinh | D19: M223 | E19: =+SUMIF(Bang_TSCD!$B$16:$B$5000,M210,Bang_TSCD!$S$16:$S$5000) | G19: KHAC | H19: TM muc 9: khau hao trong nam lay tu Bang_TSCD | K19: canh=trai|giua|phai doc=tren|giua|duoi wrap=0 rong=12 cao=16
A20: VA26093001_12 | B20: CONGTHUC | C20: TMinh | D20: Q223 | E20: =+SUMIF(Bang_TSCD!$B$16:$B$5000,Q210,Bang_TSCD!$S$16:$S$5000) | G20: KHAC | H20: TM muc 9: khau hao trong nam lay tu Bang_TSCD | K20: vien=mong|dam|khong vienmau=#B9D3E8 (nen=khong là bỏ màu nền)
A21: VA26093001_13 | B21: CONGTHUC | C21: TMinh | D21: U223 | E21: =+SUMIF(Bang_TSCD!$B$16:$B$5000,U210,Bang_TSCD!$S$16:$S$5000) | G21: KHAC | H21: TM muc 9: khau hao trong nam lay tu Bang_TSCD
A22: VA26093001_14 | B22: CONGTHUC | C22: TMinh | D22: Y223 | E22: =+SUMIF(Bang_TSCD!$B$16:$B$5000,Y210,Bang_TSCD!$S$16:$S$5000) | G22: KHAC | H22: TM muc 9: khau hao trong nam lay tu Bang_TSCD | K22: CỘT G — Điều kiện:
A23: VA26093001_15 | B23: CONGTHUC | C23: TMinh | D23: AC223 | E23: =+SUMIF(Bang_TSCD!$B$16:$B$5000,AC210,Bang_TSCD!$S$16:$S$5000) | G23: KHAC | H23: TM muc 9: khau hao trong nam lay tu Bang_TSCD | K23: KHAC (mặc định) chỉ làm khi ô đang KHÁC giá trị đích → chạy lại bao nhiêu lần cũng không hại
A24: VA26093001_16 | B24: CONGTHUC | C24: TMinh | D24: K562 | E24: =+VLOOKUP(K559,Bang_CDSPSNT,4,0)/1000 | G24: KHAC | H24: TM muc 27: so du dau nam truoc lay tu CDSPS nam truoc | K24: TRONG chỉ làm khi ô đang trống (không đè cái khách đã nhập)
A25: VA26093001_17 | B25: CONGTHUC | C25: TMinh | D25: N562 | E25: =+VLOOKUP(N559,Bang_CDSPSNT,4,0)/1000-VLOOKUP(N559,Bang_CDSPSNT,3,0)/1000 | G25: KHAC | H25: TM muc 27: so du dau nam truoc lay tu CDSPS nam truoc | K25: LUON áp mỗi lần bấm Nâng Cấp Bố Cục, KHÔNG tính vào lời nhắc lúc mở file
A26: VA26093001_18 | B26: CONGTHUC | C26: TMinh | D26: Q562 | E26: =+VLOOKUP(Q559,Bang_CDSPSNT,4,0)/1000 | G26: KHAC | H26: TM muc 27: so du dau nam truoc lay tu CDSPS nam truoc
A27: VA26093001_19 | B27: CONGTHUC | C27: TMinh | D27: T562 | E27: =+VLOOKUP(T559,Bang_CDSPSNT,4,0)/1000 | G27: KHAC | H27: TM muc 27: so du dau nam truoc lay tu CDSPS nam truoc | K27: CỘT I — ghi x là bỏ qua dòng đó. Ba dòng VD_ ở trên là ví dụ, đang tắt.
A28: VA26093001_20 | B28: CONGTHUC | C28: TMinh | D28: W562 | E28: =+VLOOKUP(W559,Bang_CDSPSNT,4,0)/1000-VLOOKUP(W559,Bang_CDSPSNT,3,0)/1000 | G28: KHAC | H28: TM muc 27: so du dau nam truoc lay tu CDSPS nam truoc
A29: VA26093001_21 | B29: CONGTHUC | C29: TMinh | D29: Z562 | E29: =+VLOOKUP(Z559,Bang_CDSPSNT,4,0)/1000-VLOOKUP(Z559,Bang_CDSPSNT,3,0)/1000 | G29: KHAC | H29: TM muc 27: so du dau nam truoc lay tu CDSPS nam truoc | K29: Nút «Bảng Vá Bố Cục» trên Ribbon: xem còn việc nào chờ + mở bảng ra sửa.
A30: VA26093001_22 | B30: CONGTHUC | C30: TMinh | D30: AC562 | E30: =+VLOOKUP(AC559,Bang_CDSPSNT,4,0)/1000-VLOOKUP(AC559,Bang_CDSPSNT,3,0)/1000 | G30: KHAC | H30: TM muc 27: so du dau nam truoc lay tu CDSPS nam truoc | K30: Việc gì KHÔNG khai báo được (chèn/xoá cột, đổi giao diện cả sheet) thì vẫn phải viết
A31: VA26093001_23 | B31: CONGTHUC | C31: TMinh | D31: AF562 | E31: =+VLOOKUP(AF559,Bang_CDSPSNT,4,0)/1000 | G31: KHAC | H31: TM muc 27: so du dau nam truoc lay tu CDSPS nam truoc | K31: một hàm Buoc<n> trong ModBoCuc như trước.
A32: VA26093001_24 | B32: CONGTHUC | C32: TMinh | D32: K563 | E32: =+VLOOKUP(K559,Bang_CDSPSNT,6,0)/1000 | G32: KHAC | H32: TM muc 27: tang von trong nam truoc
A33: VA26093001_25 | B33: CONGTHUC | C33: TMinh | D33: AC564 | E33: =+MAX(VLOOKUP(AC559,Bang_CDSPSNT,6,0)-VLOOKUP(AC559,Bang_CDSPSNT,5,0),0)/1000 | G33: KHAC | H33: TM muc 27: lai trong nam truoc
A34: VA26093001_26 | B34: CONGTHUC | C34: TMinh | D34: AC567 | E34: =+MAX(VLOOKUP(AC559,Bang_CDSPSNT,5,0)-VLOOKUP(AC559,Bang_CDSPSNT,6,0),0)/1000 | G34: KHAC | H34: TM muc 27: lo trong nam truoc
A35: VA26093001_27 | B35: CONGTHUC | C35: TMinh | D35: AL784 | E35: =IF(SUM(Y784:AK784)>1,1,0) | G35: KHAC | H35: TM: an/hien dong ghi chu (*) theo so lieu
A36: VA260930_MB7_01 | B36: GIATRI | C36: KIEMTRA | D36: E10 | E36: 2 | G36: KHAC | H36: BR cot Thang: BatBuoc 2 = chi bat buoc khi dong co dinh khoan (khong dinh khoan -> bo qua, khong len NKC, khong bao loi)
A37: VA260930_MB7_02 | B37: GIATRI | C37: KIEMTRA | D37: E19 | E37: 2 | G37: KHAC | H37: MV cot Thang ke khai: BatBuoc 2 = chi bat buoc khi dong co dinh khoan
A38: VA260930_MB8_01 | B38: GIATRI | C38: 05KK_89 | D38: F1 | E38: Khai theo: | G38: KHAC | H38: TNCN quy TT89: nhan chon kieu khai
A39: VA260930_MB8_02 | B39: CONGTHUC | C39: 05KK_89 | D39: F2 | E39: =IF($G$1="","","Chọn "&$G$1&" kết chuyển:") | G39: KHAC | H39: TNCN quy TT89: nhan chon ky
A40: VA260930_MB8_03 | B40: GIATRI | C40: 05KK_89 | D40: G1 | E40: quý | G40: TRONG | H40: TNCN quy TT89: mac dinh khai theo quy (chi khi o trong)
...

Sheet TTDN
A1: 5 | D1: THÔNG TIN DOANH NGHIỆP | AM1: Năm | AN1: Tháng | AO1: Quý | AR1: TÊN | AS1: TÊN TRÊN BÌA | AT1: GHI CHÚ | AU1: TK cấp 1 | AV1: TK cấp 2 | AW1: Sô hiệu | BM1: BẢNG THEO DÕI VAT | CD1: VÙNG TẠM LÀM SỔ KHO | CW1: BẢNG THEO DÕI VAT
AM2: =YEAR(KB_Den) -> 2026 | AN2: 1 | AO2: I | AR2: Sổ kế toán | BN2: DK | BO2: 1 | BP2: 2 | BQ2: 3 | BR2: 4 | BS2: 5 | BT2: 6 | BU2: 7 | BV2: 8 | BW2: 9 | BX2: 10 | BY2: 11 | BZ2: 12 | CD2: Tháng | CE2: Số HĐ | CF2: Ngày HĐ | CG2: Nội Dung | CH2: SL Nhập | CI2: DG Nhập | CJ2: TT nhập | CK2: SL Xuất | CL2: DG Xuất | CM2: TT Xuất | CN2: SL Tồn | CO2: DG Tồn | CP2: TT Tồn | CX2: DK | CY2: {=TRANSPOSE(Thang)} -> 1 | CZ2: 2 | DA2: 3 | DB2: 4 | DC2: 5 | DD2: 6 | DE2: 7 | DF2: 8 | DG2: 9 | DH2: 10 | DI2: 11 | DJ2: 12
A3: LẤY DỮ LIỆU | AN3: 2 | AO3: II | AR3: Sổ cái | BM3: Nợ 133 | CV3: 1 | CW3: Nợ 133
AL4: Main | AN4: 3 | AO4: III | AR4: Nhật ký chung | AS4: NHẬT KÝ CHUNG | AZ4: BẢNG KÊ HOÁ ĐƠN, CHỨNG TỪ HÀNG HOÁ, DỊCH VỤ BÁN RA | BM4: Nợ 3331 - nộp thuế | BO4: 0 | CV4: 2 | CW4: Nợ 133-dùng chung
E5: Tên doanh nghiệp: | AL5: CPU | AM5: BFEBFBFF000206A7 | AN5: 4 | AO5: IV | AR5: Sổ quỹ tiền mặt | AS5: QUỸ TIỀN MẶT | AT5: Loại quỹ: | BM5: Có 3331 | CV5: 3 | CW5: Có 133-DCQT
AL6: SecertKey | AM6: ABCDEFGHIJ | AN6: 5 | AR6: Sổ tiền gửi ngân hàng | AS6: TIỀN GỬI NGÂN HÀNG | AU6: - Tài khoản cấp I:……………………………. | AV6: - Tài khoản cấp II:……………………………. | AW6: Số hiệu tài khoản ngân hàng: | AZ6: (Kèm theo tờ khai thuế GTGT theo mẫu số 01/GTGT) | BM6: CK Khấu Trừ | BN6: 0 | BO6: 0 | BP6: 0 | BQ6: 0 | BR6: 0 | BS6: 0 | BT6: 0 | BU6: 0 | BV6: 0 | BW6: 0 | BX6: 0 | BY6: 0 | BZ6: 0 | CV6: 4 | CW6: Nợ 3331 - nộp thuế,DC
E7: Địa chỉ: | AN7: 6 | AR7: Sổ chi tiết vật liệu, sản phẩm, hàng hóa | AS7: VẬT LIỆU, SẢN PHẨM, HÀNG HÓA | AU7: TÀI KHOẢN:……………………………………. | AV7: TIỂU KHOẢN:………………………………….. | AW7: KHO: | AZ7: Kỳ tính thuế: Tháng....... năm ........../ Quý ….. Năm…… | BM7: CK Phải nộp | BN7: 0 | BO7: 0 | BP7: 0 | BQ7: 0 | BR7: 0 | BS7: 0 | BT7: 0 | BU7: 0 | BV7: 0 | BW7: 0 | BX7: 0 | BY7: 0 | BZ7: 0 | CV7: 5 | CW7: Có 3331
AN8: 7 | AR8: Sổ tài sản cố định | AS8: TÀI SẢN CỐ ĐỊNH | CV8: 6 | CW8: Có 3331-DCQT
E9: Mã số thuế: | J9: Email: | AN9: 8 | AR9: Sổ nhật ký chi tiền | AS9: NHẬT KÝ CHI TIỀN | AZ9: Người nộp thuế:........................................................................................ | CV9: 7 | CW9: CK 133
AN10: 9 | AR10: Sổ nhật ký thu tiền | AS10: NHẬT KÝ THU TIỀN | AZ10: Mã số thuế: ............................................................................................... | BM10: 0 | BN10: 1 | BO10: 2 | BP10: 3 | BQ10: 4 | BR10: 5 | BS10: 6 | BT10: 7 | BU10: 8 | BV10: 9 | BW10: 10 | BX10: 11 | BY10: 12 | CV10: 8 | CW10: CK 33311
E11: Điện thoại: | J11: Fax: | AN11: 10 | AR11: Sổ nhật ký mua hàng | AS11: NHẬT KÝ MUA HÀNG | BN11: VÙNG TẠM LÀM CÔNG NỢ | CV11: 9 | CW11: CK133 khấu trừ
A12: XÓA DỮ LIỆU | AN12: 11 | AR12: Sổ nhật ký bán hàng | AS12: NHẬT KÝ BÁN HÀNG | AZ12: Đơn vị tiền: đồng Việt Nam | BT12: Phát sinh | BV12: Phát Sinh Ngân Hàng | BX12: Cuối Kỳ
A13: 26101601 | F13: Từ ngày | K13: Đến ngày | AN13: 12 | AR13: Sổ chi phí sản xuất kinh doanh | AS13: CHI PHÍ SẢN XUẤT KINH DOANH | AU13: Tài khoản: | AZ13: STT | BA13: Hóa đơn, chứng từ bán ra | BE13: Tên người mua | BF13: Mã số thuế người mua | BG13: Mặt hàng | BH13: Doanh thu chưa có thuế GTGT | BI13: Thuế GTGT | BJ13: Ghi chú | BM13: Tháng | BN13: Ký hiệu HĐ | BO13: Số HĐ | BP13: Ngày | BQ13: Tên đơn vị mua hàng | BR13: Mã số thuế | BS13: Nội dung | BT13: Nợ | BU13: Có | BV13: Nợ | BW13: Có | BX13: Nợ | BY13: Có
E14: Kỳ kế toán: | F14: 46023 | K14: 46387 | AR14: Sổ chi tiết thanh toán | AS14: CHI TIẾT THANH TOÁN | AT14: Với người mua, người bán | AU14: Tài khoản:
AM15: KCT | AR15: Sổ chi tiết các tài khoản | AS15: CHI TIẾT CÁC TÀI KHOẢN | AU15: Tài khoản: | BA15: Ký hiệu mẫu HĐ | BB15: Ký hiệu HĐ | BC15: Số hoá đơn | BD15: Ngày, tháng, năm lập hóa đơn
E16: Thuế suất TNDN: | J16: Khai thuế GTGT theo: | K16: Theo tháng | AM16: 0 | AZ16: [1] | BA16: [2] | BB16: [3] | BC16: [4] | BD16: [5] | BE16: [6] | BF16: [7] | BG16: [8] | BH16: [9] | BI16: [10] | BJ16: [11]
AM17: 5
E18: Pass vào hóa đơn: | J18: Kết chuyển VAT: | K18: Tự động | AM18: 10 | AR18: TRUE | AS18: Check phân bổ khấu hao
AR19: TRUE | AS19: Check kết chuyển cuối kỳ
AM20: DR | AN20: Dùng riêng SXKD - được khấu trừ | AR20: TRUE | AS20: Check kéo hàng
E21: Người đại diện pháp luật | I21: Kế toán trưởng | M21: Thủ quỹ | AM21: DC | AN21: Dùng chung SXKD - được khấu trừ | AR21: FALSE | AS21: Check vat theo số người dùng
AM22: DT | AN22: Dùng cho hoạt động đầu tư | AZ22: BẢNG KÊ HOÁ ĐƠN, CHỨNG TỪ HÀNG HOÁ, DỊCH VỤ MUA VÀO
AM23: HDTT | AN23: Hóa đơn trực tiếp
AM24: 01 | AN24: Không chịu thuế GTGT | AO24: KCT | AZ24: (Kèm theo tờ khai thuế GTGT theo mẫu số 01/GTGT)
AM25: 02 | AN25: Chịu thuế GTGT 0% | AO25: 0 | AR25: tthai | AS25: Trạng thái hóa đơn MUA | AZ25: Kỳ tính thuế: Tháng....... năm ........../ Quý …. Năm….
AM26: 03 | AN26: Chịu thuế GTGT 5% | AO26: 0.05 | AR26: All | AS26: Tất cả
AM27: 04 | AN27: Chịu thuế GTGT 10% | AO27: 0.1 | AR27: 1 | AS27: Hóa đơn mới | AZ27: Người nộp thuế:........................................................................................
F28: TÙY CHỌN HỆ THỐNG | AR28: 2 | AS28: Hóa đơn thay thế | AZ28: Mã số thuế: ...............................................................................................
AR29: 3 | AS29: Hóa đơn điều chỉnh
AR30: 4 | AS30: Hóa đơn bị thay thế | AZ30: Đơn vị tiền: đồng Việt Nam
AM31: CDSPSNT_TK | AN31: =+"CDSPS_NT!"&ADDRESS(ROW(CDSPS_NT_1)+1,COLUMN(CDSPS_NT_1))&":"&ADDRESS(ROW(CDSPS_NT_TC)-1,COLUMN(CDSPS_NT_1)) -> CDSPS_NT!$C$15:$C$432 | AR31: 5 | AS31: Hóa đơn đã bị điều chỉnh | AZ31: STT | BA31: Hóa đơn, biên lai, chứng từ nộp thuế | BE31: Tên người bán | BF31: Mã số thuế người bán | BG31: Mặt hàng | BH31: Giá trị HHDV mua vào chưa có thuế | BI31: Thuế suất | BJ31: Thuế GTGT đủ điều kiện khấu trừ thuế | BK31: Ghi chú
I32: Kết chuyển tự động Lãi/Lỗ đầu năm: | J32: Yes | AM32: CDSPSNT_DKN | AN32: =+"CDSPS_NT!"&ADDRESS(ROW(CDSPS_NT_1)+1,COLUMN(CDSPS_NT_1)+2)&":"&ADDRESS(ROW(CDSPS_NT_TC)-1,COLUMN(CDSPS_NT_1)+2) -> CDSPS_NT!$E$15:$E$432 | AR32: 6 | AS32: Hóa đơn bị hủy
AM33: CDSPSNT_DKC | AN33: =+"CDSPS_NT!"&ADDRESS(ROW(CDSPS_NT_1)+1,COLUMN(CDSPS_NT_1)+3)&":"&ADDRESS(ROW(CDSPS_NT_TC)-1,COLUMN(CDSPS_NT_1)+3) -> CDSPS_NT!$F$15:$F$432 | BA33: Ký hiệu mẫu HĐ | BB33: Ký hiệu HĐ | BC33: Số hoá đơn | BD33: Ngày, tháng, năm lập hóa đơn
I34: Kết chuyển tự động Phân bổ - Khấu hao: | J34: Yes | AM34: CDSPSNT_PSN | AN34: =+"CDSPS_NT!"&ADDRESS(ROW(CDSPS_NT_1)+1,COLUMN(CDSPS_NT_1)+4)&":"&ADDRESS(ROW(CDSPS_NT_TC)-1,COLUMN(CDSPS_NT_1)+4) -> CDSPS_NT!$G$15:$G$432 | AR34: ttxly | AS34: Kết quả kiểm tra MUA | AZ34: [1] | BA34: [2] | BB34: [3] | BC34: [4] | BD34: [5] | BE34: [6] | BF34: [7] | BG34: [8] | BH34: [9] | BI34: [10] | BJ34: [11] | BK34: [12]
AM35: CDSPSNT_PSC | AN35: =+"CDSPS_NT!"&ADDRESS(ROW(CDSPS_NT_1)+1,COLUMN(CDSPS_NT_1)+5)&":"&ADDRESS(ROW(CDSPS_NT_TC)-1,COLUMN(CDSPS_NT_1)+5) -> CDSPS_NT!$H$15:$H$432 | AR35: All | AS35: Tất cả
I36: Kết chuyển tự động DT-CP qua 911: | J36: Yes | AM36: CDSPSNT_CKN | AN36: =+"CDSPS_NT!"&ADDRESS(ROW(CDSPS_NT_1)+1,COLUMN(CDSPS_NT_1)+6)&":"&ADDRESS(ROW(CDSPS_NT_TC)-1,COLUMN(CDSPS_NT_1)+6) -> CDSPS_NT!$I$15:$I$432 | AR36: 5 | AS36: Đã cấp mã hóa đơn
AM37: CDSPSNT_CKC | AN37: =+"CDSPS_NT!"&ADDRESS(ROW(CDSPS_NT_1)+1,COLUMN(CDSPS_NT_1)+7)&":"&ADDRESS(ROW(CDSPS_NT_TC)-1,COLUMN(CDSPS_NT_1)+7) -> CDSPS_NT!$J$15:$J$432 | AR37: 6 | AS37: Tổng cục thuế đã nhận không mã
J38: 0 | AR38: 8 | AS38: Tổng cục thuế đã nhận hóa đơn có mã khởi tạo từ máy tính tiền
AM39: https://www.dropbox.com/s/c6cttmr06r2410i/
J40: 0 | AM40: https://www.dropbox.com/s/zk86rb8thuycbl2/ | AR40: ttxly | AS40: Kết quả kiểm tra BAN
...

Sheet LuuY
B2: VÙNG KHAI BÁO CÁC BÚT TOÁN ĐỊNH KHOẢN NHANH
B3: Sheet | C3: STT | D3: Nội dung | E3: ĐK nợ | F3: ĐK có
B4: [1] | C4: [2] | D4: [3] | E4: [4] | F4: [5] | H4: BÁN RA - NHẬT KÝ BÁN | V4: Gõ mã tài khoản vào hai hàng mã bên dưới, theo từng CẶP cần so (cột NK thứ k <-> cột bảng kê thứ k). Để trống thì bỏ qua cặp đó.
B5: BR | C5: 1 | D5: TM_doanh thu Thương Mại | E5: 1111 | F5: 5111 | H5: Tháng | I5: NK bán | M5: Bảng kê Bán ra | Q5: Chênh lệch (NK - bảng kê)
B6: BR | C6: 2 | D6: TM_doanh thu Sản xuất | E6: 1111 | F6: 5112
B7: BR | C7: 3 | D7: TM_doanh thu xây dựng | E7: 1111 | F7: 5113 | H7: 1
B8: MV | C8: 1 | D8: TM_6428 | E8: 6428 | H8: 2
B9: MV | C9: 2 | D9: TM_6427 | E9: 6427 | H9: 3
H10: 4
H11: 5
H12: 6
H13: 7
H14: 8
H15: 9
H16: 10
H17: 11
H18: 12
H19: TC | I19: =SUM(I7:I18) -> 0 | J19: =SUM(J7:J18) -> 0 | K19: =SUM(K7:K18) -> 0 | L19: =SUM(L7:L18) -> 0 | M19: =SUM(M7:M18) -> 0 | N19: =SUM(N7:N18) -> 0 | O19: =SUM(O7:O18) -> 0 | P19: =SUM(P7:P18) -> 0 | ... T19: =SUM(T7:T18) -> 0
H22: MUA VÀO - NHẬT KÝ MUA | V22: Gõ mã tài khoản vào hai hàng mã bên dưới, theo từng CẶP cần so (cột NK thứ k <-> cột bảng kê thứ k). Để trống thì bỏ qua cặp đó.
H23: Tháng | I23: NK mua | M23: Bảng kê Mua vào | Q23: Chênh lệch (NK - bảng kê)
H25: 1
H26: 2
H27: 3
H28: 4
H29: 5
H30: 6
H31: 7
H32: 8
H33: 9
H34: 10
H35: 11
H36: 12
H37: TC | I37: =SUM(I25:I36) -> 0 | J37: =SUM(J25:J36) -> 0 | K37: =SUM(K25:K36) -> 0 | L37: =SUM(L25:L36) -> 0 | M37: =SUM(M25:M36) -> 0 | N37: =SUM(N25:N36) -> 0 | O37: =SUM(O25:O36) -> 0 | P37: =SUM(P25:P36) -> 0 | ... T37: =SUM(T25:T36) -> 0

Sheet BAO_LOI
A1: BÁO CÁO KIỂM TRA DỮ LIỆU NHẬP
A5: STT | B5: Sheet | C5: Ô (bấm để tới) | D5: Giá trị đang có | E5: Lỗi | F5: Cách sửa

Sheet LayHDXML
B1: x | K1: Hyperlink lấy File PDF: | L1: Yes
K2: Lấy lại DATA làm hóa đơn: | L2: No
K4: =+SUBTOTAL(9,K8:K1478) -> 0 | M4: =+SUBTOTAL(9,M8:M1478) -> 0 | N4: =+SUBTOTAL(9,N8:N1478) -> 0 | AA4: Danh sách các hóa đơn chưa có
B5: Thông tin hóa đơn | G5: Thông tin bên bán | J5: Nội dung hóa đơn | O5: Thông tin bên mua | R5: Thông tin tra cứu | AA5: Thông tin hóa đơn | AE5: Thông tin khách hàng | AG5: Tiền hóa đơn
B6: Mẫu số | C6: Ký hiệu | D6: Số hóa đơn | E6: Ngày lập hóa đơn | F6: Ngày ký hóa đơn | G6: Tên người bán | H6: Mã số thuế | I6: Địa chỉ | J6: Nội dung | K6: Thành tiền chưa có VAT | L6: Thuế suất | M6: Thuế GTGT | N6: Tổng hóa đơn | O6: Tên người mua | P6: Mã số thuế | Q6: Địa chỉ | R6: Link tra cứu | S6: Mã tra cứu | T6: Mã cơ quan thuế | U6: Ngày TCT ký | V6: Hyperlink | W6: Ghi chú | X6: Kiểm tra với Chi tiết | Y6: Kiểm tra với Web HĐ | AA6: Mẫu số | AB6: Ký hiệu | AC6: Số hóa đơn | AD6: Ngày lập hóa đơn | AE6: Tên khách hàng | AF6: Mã số thuế | AG6: Tổng tiền chưa thuế | AH6: Thuế GTGT | AI6: Tổng hóa đơn
B7: [1] | C7: [2] | D7: [3] | E7: [4] | F7: [5] | G7: [6] | H7: [7] | I7: [8] | J7: [9] | K7: [10] | L7: [11] | M7: [12] | N7: [13] | O7: [14] | P7: [15] | Q7: [16] | R7: [17] | S7: [18] | T7: [19] | U7: [20] | V7: [21] | W7: [22] | X7: [23] | Y7: [24] | AA7: [1] | AB7: [2] | AC7: [3] | AD7: [4] | AE7: [5] | AF7: [6] | AG7: [7] | AH7: [8] | AI7: [9]

Sheet NK_HDXML
M4: =+SUBTOTAL(9,M8:M1478) -> 0 | O4: =+SUBTOTAL(9,O8:O1478) -> 0
B5: Thông tin HĐ | F5: Người bán/Người mua | H5: Chi tiết mua vào | Q5: Kiểm tra với Mua vào
B6: Mẫu số | C6: Ký hiệu | D6: Số hóa đơn | E6: Ngày hóa đơn | F6: Tên người bán/Mua | G6: Mã số thuế | H6: Mã hàng | I6: Tên hàng | J6: Đơn vị tính | K6: Số lượng | L6: Đơn giá | M6: Thành tiền | N6: Thuế suất (%) | O6: Tiền thuế | P6: Ghi chú
B7: [1] | C7: [2] | D7: [3] | E7: [4] | F7: [5] | G7: [6] | H7: [7] | I7: [8] | J7: [9] | K7: [10] | L7: [11] | M7: [12] | N7: [13] | O7: [14] | P7: [15] | Q7: [16]

Sheet HOADON
I5: =+SUBTOTAL(9,I8:I994) -> 0 | K5: =+SUBTOTAL(9,K8:K994) -> 0 | L5: =+SUBTOTAL(9,L8:L994) -> 0 | M5: =+SUBTOTAL(9,M8:M994) -> 0 | N5: =+SUBTOTAL(9,N8:N994) -> 0 | U5: Đối chiếu VAT | Y5: Đối chiếu Thành tiền | AC5: Hóa đơn liên quan
A6: STT | B6: Ký hiệu mẫu số | C6: Ký hiệu hóa đơn | D6: Số hóa đơn | E6: Ngày lập | F6: Tên người mua/Tên người nhận hàng | G6: MST người mua/MST người nhận hàng | H6: Nội dung | I6: Tổng tiền chưa thuế | J6: Thuế suất | K6: Tổng tiền thuế | L6: Tổng tiền CKTM | M6: Tổng tiền phí | N6: Tổng tiền thanh toán | O6: Đơn vị tiền tệ | P6: Trạng thái hóa đơn | Q6: Kết quả kiểm tra hóa đơn | R6: Tháng | S6: Loại chứng từ | U6: Tổng tiền VAT | V6: VAT bên MV/BR | W6: Đối chiếu | Y6: Tổng tiền hàng | Z6: Tiền hàng bên MV/BR | AA6: Đối chiếu | AC6: Chuỗi thay thế / điều chỉnh | AD6: Thông báo sai sót (04/SS)
A7: [1] | B7: [2] | C7: [3] | D7: [4] | E7: [5] | F7: [6] | G7: [7] | H7: [8] | I7: [9] | J7: [10] | K7: [11] | L7: [12] | M7: [13] | N7: [14] | O7: [15] | P7: [16] | Q7: [17] | R7: [18] | S7: [19] | U7: [1] | V7: [2] | W7: [3] | Y7: [1] | Z7: [2] | AA7: [3] | AC7: [1] | AD7: [2]

Sheet BR
A1: 3
A4: Chú ý: Bạn muốn thêm khách hàng nào để theo dõi công nợ thì để 'Chuột' vào dòng đó rồi thực hiện lệnh 'Thêm Công Nợ' | I4: =+SUBTOTAL(9,I8:I1478) -> 0 | K4: =+SUBTOTAL(9,K8:K1478) -> 0 | R4: =+SUBTOTAL(9,R8:R1478) -> 0 | S4: Mã Đ/C ? | T4: Vùng kiểm tra | Y4: TỔNG HỢP BÁN RA
A5: Loại | B5: Ký hiệu mẫu HĐ | C5: Ký Hiệu HĐ | D5: Số HĐ | E5: Ngày HĐ | F5: Tên khách hàng mua | G5: MST | H5: Nội Dung | I5: Thành tiền | J5: Thuế suất | K5: VAT | L5: Ghi chú | M5: Định Khoản | Q5: Tháng | R5: Tổng HĐ | S5: Mã Đ/C | T5: TT & VAT | U5: Bra & Nky | V5: T.toán NH | W5: Kê khai TCT
M6: Đ/K thành tiền | O6: Đ/K VAT | S6: HĐ điều chỉnh
A7: [1] | B7: [2] | C7: [3] | D7: [4] | E7: [5] | F7: [6] | G7: [7] | H7: [8] | I7: [9] | J7: [10] | K7: [11] | L7: [12] | M7: Nợ | N7: Có | O7: Nợ | P7: Có | Q7: [13] | R7: [14] | S7: [15] | T7: [1] | U7: [2] | V7: [3] | W7: [4] | Y7: Tháng | Z7: Doanh số bán ra | AA7: VAT
R8: =$I8+$K8 -> 0 | Y8: {=Thang} -> 1
R9: =$I9+$K9 -> 0 | Y9: 2
R10: =$I10+$K10 -> 0 | Y10: 3
R11: =$I11+$K11 -> 0 | Y11: 4
R12: =$I12+$K12 -> 0 | Y12: 5
R13: =$I13+$K13 -> 0 | Y13: 6
R14: =$I14+$K14 -> 0 | Y14: 7
R15: =$I15+$K15 -> 0 | Y15: 8
R16: =$I16+$K16 -> 0 | Y16: 9
R17: =$I17+$K17 -> 0 | Y17: 10
R18: =$I18+$K18 -> 0 | Y18: 11
R19: =$I19+$K19 -> 0 | Y19: 12
R20: =$I20+$K20 -> 0
R21: =$I21+$K21 -> 0 | Y21: Tổng cộng | Z21: =+SUM(Z8:Z20) -> 0 | AA21: =+SUM(AA8:AA20) -> 0
R22: =$I22+$K22 -> 0
R23: =$I23+$K23 -> 0
R24: =$I24+$K24 -> 0 | Y24: Quý | Z24: Doanh số bán ra | AA24: VAT
R25: =$I25+$K25 -> 0 | Y25: {=Quy} -> I | Z25: =+Z8+Z9+Z10 -> 0 | AA25: =+AA8+AA9+AA10 -> 0
R26: =$I26+$K26 -> 0 | Y26: II | Z26: =+Z11+Z12+Z13 -> 0 | AA26: =+AA11+AA12+AA13 -> 0
R27: =$I27+$K27 -> 0 | Y27: III | Z27: =+Z14+Z15+Z16 -> 0 | AA27: =+AA14+AA15+AA16 -> 0
R28: =$I28+$K28 -> 0 | Y28: IV | Z28: =+Z17+Z18+Z19 -> 0 | AA28: =+AA17+AA18+AA19 -> 0
R29: =$I29+$K29 -> 0
R30: =$I30+$K30 -> 0 | Y30: Tổng cộng | Z30: =SUM(Z25:Z29) -> 0 | AA30: =SUM(AA25:AA29) -> 0
R31: =$I31+$K31 -> 0
R32: =$I32+$K32 -> 0
R33: =$I33+$K33 -> 0
R34: =$I34+$K34 -> 0
R35: =$I35+$K35 -> 0
R36: =$I36+$K36 -> 0
R37: =$I37+$K37 -> 0
R38: =$I38+$K38 -> 0
R39: =$I39+$K39 -> 0
R40: =$I40+$K40 -> 0
R41: =$I41+$K41 -> 0
R42: =$I42+$K42 -> 0
...

Sheet NK_Ban
I1: Kiểm tra để công thức: | J1: N
G5: =+SUBTOTAL(9,$G$8:G526) -> 0 | I5: =+SUBTOTAL(9,$I$8:I526) -> 0 | O5: Vùng kiểm tra
A6: Tháng | B6: Số HĐ | C6: Ngày HĐ | D6: Mã HH, DV,TP | E6: Tên HH, DV, TP | F6: ĐVT | G6: Số lượng | H6: Đơn giá | I6: Thành tiền | J6: Định khoản | K6: Số phiếu xuất | L6: Tên khách hàng mua | M6: Kho xuất | N6: Ghi chú | O6: K.Tra N.Ký & B.Ra | P6: Đơn giá vốn | Q6: Tỷ lệ
A7: [1] | B7: [2] | C7: [3] | D7: [4] | E7: [5] | F7: [6] | G7: [7] | H7: [8] | I7: [9] | J7: [10] | K7: [11] | L7: [12] | M7: [13] | N7: [14] | O7: [15] | P7: [16] | Q7: [17]
I8: =$G8*$H8 -> 0
I9: =$G9*$H9 -> 0
I10: =$G10*$H10 -> 0
I11: =$G11*$H11 -> 0
I12: =$G12*$H12 -> 0
I13: =$G13*$H13 -> 0
I14: =$G14*$H14 -> 0
I15: =$G15*$H15 -> 0
I16: =$G16*$H16 -> 0
I17: =$G17*$H17 -> 0
I18: =$G18*$H18 -> 0
I19: =$G19*$H19 -> 0
... I1405: =$G1405*$H1405 -> 0

Sheet MV
A1: 1
A4: Chú ý: Bạn muốn thêm khách hàng nào để theo dõi công nợ thì để 'Chuột' vào dòng đó rồi thực hiện lệnh 'Thêm Công Nợ' | I4: =+SUBTOTAL(9,I8:I1478) -> 0 | K4: =+SUBTOTAL(9,K8:K1478) -> 0 | R4: =+SUBTOTAL(9,R8:R1478) -> 0 | T4: Mã Đ/C ? | U4: Vùng kiểm tra
A5: Loại | B5: Ký hiệu mẫu HĐ | C5: Ký hiệu HĐ | D5: Số HĐ | E5: Ngày HĐ | F5: Tên người bán | G5: Mã số thuế người bán | H5: Mặt hàng | I5: Thành tiền chưa có VAT | J5: Thuế suất | K5: VAT | L5: Ghi chú | M5: Định Khoản | Q5: Tg kê khai BCT | R5: Tổng HĐ | S5: Tg ghi sổ | T5: Mã Đ/C | U5: TT & VAT | V5: M.Vào & N.Ký | W5: T.toán NH | X5: Trùng HĐ | Y5: Kê khai TCT | AA5: TỔNG HỢP MUA VÀO
M6: Đ/K thành tiền | O6: Đ/K VAT | T6: HĐ điều chỉnh
A7: [1] | B7: [2] | C7: [3] | D7: [4] | E7: [5] | F7: [6] | G7: [7] | H7: [8] | I7: [9] | J7: [10] | K7: [11] | L7: [12] | M7: Nợ | N7: Có | O7: Nợ | P7: Có | Q7: [13] | R7: [14] | S7: [15] | T7: [16] | U7: [1] | V7: [2] | W7: [3] | X7: [4] | Y7: [5] | AA7: Tháng | AB7: Doanh số mua vào | AC7: VAT
R8: =$I8+$K8 -> 0 | AA8: {=Thang} -> 1
R9: =$I9+$K9 -> 0 | AA9: 2
R10: =$I10+$K10 -> 0 | AA10: 3
R11: =$I11+$K11 -> 0 | AA11: 4
R12: =$I12+$K12 -> 0 | AA12: 5
R13: =$I13+$K13 -> 0 | AA13: 6
R14: =$I14+$K14 -> 0 | AA14: 7
R15: =$I15+$K15 -> 0 | AA15: 8
R16: =$I16+$K16 -> 0 | AA16: 9
R17: =$I17+$K17 -> 0 | AA17: 10
R18: =$I18+$K18 -> 0 | AA18: 11
R19: =$I19+$K19 -> 0 | AA19: 12
R20: =$I20+$K20 -> 0
R21: =$I21+$K21 -> 0 | AA21: Tổng cộng | AB21: =+SUM(AB8:AB20) -> 0 | AC21: =+SUM(AC8:AC20) -> 0
R22: =$I22+$K22 -> 0
R23: =$I23+$K23 -> 0
R24: =$I24+$K24 -> 0 | AA24: Quý | AB24: Doanh số mua vào | AC24: VAT
R25: =$I25+$K25 -> 0 | AA25: {=Quy} -> I | AB25: =+AB8+AB9+AB10 -> 0 | AC25: =+AC8+AC9+AC10 -> 0
R26: =$I26+$K26 -> 0 | AA26: II | AB26: =+AB11+AB12+AB13 -> 0 | AC26: =+AC11+AC12+AC13 -> 0
R27: =$I27+$K27 -> 0 | AA27: III | AB27: =+AB14+AB15+AB16 -> 0 | AC27: =+AC14+AC15+AC16 -> 0
R28: =$I28+$K28 -> 0 | AA28: IV | AB28: =+AB17+AB18+AB19 -> 0 | AC28: =+AC17+AC18+AC19 -> 0
R29: =$I29+$K29 -> 0
R30: =$I30+$K30 -> 0 | AA30: Tổng cộng | AB30: =SUM(AB25:AB29) -> 0 | AC30: =SUM(AC25:AC29) -> 0
R31: =$I31+$K31 -> 0
R32: =$I32+$K32 -> 0
R33: =$I33+$K33 -> 0
R34: =$I34+$K34 -> 0
R35: =$I35+$K35 -> 0
R36: =$I36+$K36 -> 0
R37: =$I37+$K37 -> 0
R38: =$I38+$K38 -> 0
R39: =$I39+$K39 -> 0
R40: =$I40+$K40 -> 0
R41: =$I41+$K41 -> 0
R42: =$I42+$K42 -> 0
...

Sheet NK_Mua
I1: Kiểm tra để công thức: | J1: N
G5: =+SUBTOTAL(9,$G$8:G1479) -> 0 | I5: =+SUBTOTAL(9,$I$8:I1479) -> 0 | O5: Vùng kiểm tra
A6: Tháng | B6: Số HĐ | C6: Ngày HĐ | D6: Mã HH, DV,TP | E6: Tên HH, DV, TP | F6: ĐVT | G6: Số lượng | H6: Đơn giá | I6: Thành tiền | J6: Định khoản | K6: Số phiếu nhập | L6: Tên khách hàng bán | M6: Kho nhập | N6: Ghi chú | O6: K.Tra N.Ký & M.Vào
A7: [1] | B7: [2] | C7: [3] | D7: [4] | E7: [5] | F7: [6] | G7: [7] | H7: [8] | I7: [9] | J7: [10] | K7: [11] | L7: [12] | M7: [13] | N7: [14] | O7: [15]
I8: =$G8*$H8 -> 0
I9: =$G9*$H9 -> 0
I10: =$G10*$H10 -> 0
I11: =$G11*$H11 -> 0
I12: =$G12*$H12 -> 0
I13: =$G13*$H13 -> 0
I14: =$G14*$H14 -> 0
I15: =$G15*$H15 -> 0
I16: =$G16*$H16 -> 0
I17: =$G17*$H17 -> 0
I18: =$G18*$H18 -> 0
I19: =$G19*$H19 -> 0
... I1480: =$G1480*$H1480 -> 0

Sheet NH
H4: =+SUBTOTAL(9,H8:H1478) -> 0
C5: Ký hiệu NH | D5: Ngày | E5: Tên người rút-nộp tiền | F5: Mã | G5: Nội dung | H5: Số tiền | I5: Ghi chú | J5: Định khoản | L5: Tháng
J6: Nợ | K6: Có
C7: [1] | D7: [2] | E7: [3] | F7: [4] | G7: [5] | H7: [6] | I7: [7] | J7: [8] | K7: [9] | L7: [10]

Sheet LT
H4: =+SUBTOTAL(9,H8:H1478) -> 0
C5: Ký hiệu | D5: Ngày | E5: Tên người rút-nộp tiền | F5: Mã | G5: Nội dung | H5: Số tiền | I5: Ghi chú | J5: Định khoản | L5: Tháng
J6: Nợ | K6: Có
C7: [1] | D7: [2] | E7: [3] | F7: [4] | G7: [5] | H7: [6] | I7: [7] | J7: [8] | K7: [9] | L7: [10]
B13: 45064
B14: 45064

Sheet SDDK_CN
B4: BẢNG THEO DÕI CÔNG NỢ PHẢI THU (131;141;1388) | L4: BẢNG THEO DÕI CÔNG NỢ PHẢI TRẢ (331;3388;335;341) | U4: BẢNG THEO DÕI ĐỊNH KHOẢN TỰ ĐỘNG
E5: =+SUBTOTAL(9,E$8:$E226) -> 0 | F5: =+SUBTOTAL(9,F$8:F226) -> 0 | O5: =+SUBTOTAL(9,$O$8:O226) -> 0 | P5: =+SUBTOTAL(9,$P$8:P226) -> 0
B6: Tên đối tượng công nợ | C6: Mã số thuế | D6: Ký hiệu | E6: Đầu kỳ nợ | F6: Đầu kỳ có | G6: Trùng MST | H6: Trùng TK | I6: Định khoản có | L6: Tên đối tượng công nợ | M6: Mã số thuế | N6: Ký hiệu | O6: Đầu kỳ nợ | P6: Đầu kỳ có | Q6: Trùng MST | R6: Trùng TK | S6: Định khoản nợ | U6: Mã NV | V6: Tên khách hàng | W6: Mã số thuế | X6: Định khoản Nợ | Y6: Định khoản Có
B7: [1] | C7: [2] | D7: [3] | E7: [4] | F7: [5] | G7: [6] | H7: [7] | I7: [8] | L7: [1] | M7: [2] | N7: [3] | O7: [4] | P7: [5] | Q7: [6] | R7: [7] | S7: [8] | U7: [1] | V7: [2] | W7: [3] | X7: [4] | Y7: [5]

Sheet CN_TH
A1: 1 | C1: Chọn nhóm công nợ: | D1: Phải thu
A2: 12 | C2: Muốn xem chi tiết công nợ nào thì để chuột tại dòng công nợ đó và thực hiện lệnh "Xem chi Tiết"
B4: =+CDSPS!$C$5 -> Đơn vị :
B5: =+CDSPS!$C$6 -> Địa chỉ :
B6: =+CDSPS!$C$7 -> Mã số thuế :
B7: =" BẢNG TỔNG HỢP CÔNG NỢ "&UPPER($D$1) -> BẢNG TỔNG HỢP CÔNG NỢ PHẢI THU
B8: Từ tháng 1 đến tháng 12 năm 2026
K9: Đơn vị tính: đồng Việt Nam
B10: STT | C10: Tên khách hàng | D10: Mã số thuế | E10: Ký hiệu | F10: Số dư đầu kỳ | H10: Số phát sinh | J10: Số dư cuối kỳ
F11: Nợ | G11: Có | H11: Nợ | I11: Có | J11: Nợ | K11: Có
B12: [1] | C12: [2] | D12: [3] | E12: [4] | F12: [5] | G12: [6] | H12: [7] | I12: [8] | J12: [9] | K12: [10]
C15: Tổng cộng
I17: Ngày 31 tháng 12 năm 2026
C18: Người lập biểu Kế toán trưởng | I18: Người đại diện theo pháp luật
C19: (Ký, họ tên) (Ký, họ tên) | I19: (Ký, họ tên, đóng dấu)
I25: =KB_GD -> 0

Sheet CN_CTiet
G1: Chọn nhóm công nợ: | H1: Phải thu | J1: Bạn muốn xử lý nghiệp vụ nào thì để chuột tại nghiệp vụ đó và thực hiện lệnh
C5: =+CDSPS!$C$5 -> Đơn vị :
C6: =+CDSPS!$C$6 -> Địa chỉ :
C7: =+CDSPS!$C$7 -> Mã số thuế :
C8: ="BẢNG CHI TIẾT CÔNG NỢ "&UPPER($H$1) -> BẢNG CHI TIẾT CÔNG NỢ PHẢI THU
F10: Ký hiệu:
F11: Tên khách hàng:
M12: Đơn vị tính: đồng Việt Nam
C13: STT | D13: Ký hiệu HĐ | E13: Số HĐ | F13: Ngày | G13: Tên đơn vị mua hàng | H13: Mã số thuế | I13: Nội dung | J13: Số phát sinh | L13: Số dư | N13: Dòng
J14: Nợ | K14: Có | L14: Nợ | M14: Có
C15: [1] | D15: [2] | E15: [3] | F15: [4] | G15: [5] | H15: [6] | I15: [7] | J15: [8] | K15: [9] | L15: [10] | M15: [11] | N15: [12]
G16: Số dư đầu kỳ
G21: Cộng phát sinh
G22: Số dư cuối kỳ

Sheet PBKH
B4: BẢNG THEO DÕI CHI PHÍ CHỜ PHÂN BỔ VÀ TÀI SẢN TRÍCH KHẤU HAO
F5: Lưu ý: Đọc kỹ các Ghi chú tại từng cột | I5: =+SUBTOTAL(9,I9:I1479) -> 0 | K5: =+SUBTOTAL(9,K9:K1479) -> 0 | S5: =+SUBTOTAL(9,S9:S1479) -> 0 | U5: =+SUBTOTAL(9,U9:U1479) -> 0 | V5: =+SUBTOTAL(9,V9:V1479) -> 0 | Y5: =+SUBTOTAL(9,Y9:Y1479) -> 0 | Z5: =+SUBTOTAL(9,Z9:Z1479) -> 0 | AA5: =+SUBTOTAL(9,AA9:AA1479) -> 0 | AB5: =+SUBTOTAL(9,AB9:AB1479) -> 0 | AC5: =+SUBTOTAL(9,AC9:AC1479) -> 0 | AD5: =+SUBTOTAL(9,AD9:AD1479) -> 0 | AE5: =+SUBTOTAL(9,AE9:AE1479) -> 0 | AF5: =+SUBTOTAL(9,AF9:AF1479) -> 0 | ... AJ5: =+SUBTOTAL(9,AJ9:AJ1479) -> 0
B6: Nhóm | C6: Định khoản CCDC-TS | D6: Số HĐ | E6: Ngày HĐ | F6: Tên TS | G6: Ngày đưa vào SD | H6: Ngày bắt đầu P.Bổ K.Hao | I6: Giá trị TS | J6: Thời gian P/Bổ KH | K6: Giá trị đã P.Bổ K.Hao năm trước | L6: TK trích P/Bổ KH | M6: Tg ghi sổ | N6: Tg tạm ngưng P.B K.H | O6: Tg P.Bổ K.Hao lại sau khi tạm ngưng | P6: Ghi giảm TS P.Bổ K.Hao | S6: Giá trị P.Bổ K.Hao 1 tháng | T6: Ghi chú | U6: Vùng lấy số dư cho đầu năm sau | Y6: 1 | Z6: 2 | AA6: 3 | AB6: 4 | AC6: 5 | AD6: 6 | AE6: 7 | AF6: 8 | AG6: 9 | AH6: 10 | AI6: 11 | AJ6: 12
P7: Số hiệu | Q7: Ngày, tháng, năm | R7: Lý do | U7: Giá trị PH-KH năm nay | V7: Giá trị còn lại | W7: Rút trích
B8: [1] | C8: [2] | D8: [3] | E8: [4] | F8: [5] | G8: [6] | H8: [7] | I8: [8] | J8: [9] | K8: [10] | L8: [11] | M8: [12] | N8: [13] | O8: [14] | P8: [15] | Q8: [16] | R8: [17] | S8: [18] | T8: [19] | U8: [20] | V8: [21] | W8: [22] | Y8: [1] | Z8: [2] | AA8: [3] | AB8: [4] | AC8: [5] | AD8: [6] | AE8: [7] | AF8: [8] | AG8: [9] | AH8: [10] | AI8: [11] | AJ8: [12]
S9: =IF($J9="",0,IF($B9="PB",$I9/$J9,$I9/($J9*12))) -> 0
S10: =IF($J10="",0,IF($B10="PB",$I10/$J10,$I10/($J10*12))) -> 0
S11: =IF($J11="",0,IF($B11="PB",$I11/$J11,$I11/($J11*12))) -> 0
S12: =IF($J12="",0,IF($B12="PB",$I12/$J12,$I12/($J12*12))) -> 0
S13: =IF($J13="",0,IF($B13="PB",$I13/$J13,$I13/($J13*12))) -> 0
S14: =IF($J14="",0,IF($B14="PB",$I14/$J14,$I14/($J14*12))) -> 0
S15: =IF($J15="",0,IF($B15="PB",$I15/$J15,$I15/($J15*12))) -> 0
S16: =IF($J16="",0,IF($B16="PB",$I16/$J16,$I16/($J16*12))) -> 0
S17: =IF($J17="",0,IF($B17="PB",$I17/$J17,$I17/($J17*12))) -> 0
S18: =IF($J18="",0,IF($B18="PB",$I18/$J18,$I18/($J18*12))) -> 0
S19: =IF($J19="",0,IF($B19="PB",$I19/$J19,$I19/($J19*12))) -> 0
S20: =IF($J20="",0,IF($B20="PB",$I20/$J20,$I20/($J20*12))) -> 0
... S290: =IF($J290="",0,IF($B290="PB",$I290/$J290,$I290/($J290*12))) -> 0

Sheet Bang_PBo
F1: Chọn tháng kết chuyển: | G1: 6
D5: ="Đơn vị : "&KB_CTy -> Đơn vị :
D6: ="Địa chỉ : "&KB_DC -> Địa chỉ :
D7: ="Mã số thuế : "&KB_MST -> Mã số thuế :
D8: BẢNG PHÂN BỔ CHI PHÍ CHỜ PHÂN BỔ
G9: Tháng | H9: 6
G10: Năm | H10: =YEAR(KB_Den) -> 2026
P11: Đơn vị tính: đồng Việt Nam
C12: Ký hiệu | D12: Chứng từ | F12: Tên chi phí | G12: Ngày đưa vào SD | H12: Ngày bắt đầu P/Bổ | I12: Giá trị ban đầu | J12: Thời gian P/Bổ | K12: Số tháng đã P/Bổ | L12: Giá trị đã P/Bổ | M12: Giá trị còn lại | N12: Giá trị P/Bổ 1 tháng | O12: Giá trị P/Bổ kỳ này | P12: Ghi chú | R12: Chi tiết phân bổ từng tháng
D13: Số hóa đơn | E13: Ngày hóa đơn | R13: 1 | S13: 2 | T13: 3 | U13: 4 | V13: 5 | W13: 6 | X13: 7 | Y13: 8 | Z13: 9 | AA13: 10 | AB13: 11 | AC13: 12
C15: [0] | D15: [1] | E15: [2] | F15: [3] | G15: [4] | H15: [5] | I15: [6] | J15: [7] | K15: [8] | L15: [9] | M15: [10] | N15: [11] | O15: [12] | P15: [13] | R15: [1] | S15: [2] | T15: [3] | U15: [4] | V15: [5] | W15: [6] | X15: [7] | Y15: [8] | Z15: [9] | AA15: [10] | AB15: [11] | AC15: [12]
F18: Tổng cộng
M20: , Ngày 30 tháng 6 năm 2025
E21: Người lập biểu | H21: Kế toán trưởng | M21: Người đại diện theo pháp luật
E22: (Ký, họ tên) | H22: (Ký, họ tên) | M22: (Ký, họ tên, đóng dấu)
E28: =IF(ISBLANK(KB_TQuy),"",KB_TQuy) | H28: =IF(ISBLANK(KB_KTT),"",KB_KTT) | M28: =KB_GD -> 0

Sheet Bang_TSCD
F1: Chọn lại tài sản: | G1: All
F2: Chọn tháng kết chuyển: | G2: 12
C5: ="Đơn vị : "&KB_CTy -> Đơn vị :
C6: ="Địa chỉ : "&KB_DC&", "&KB_TTP -> Địa chỉ : ,
C7: ="Mã số thuế : "&KB_MST -> Mã số thuế :
C8: ="SỔ THEO DÕI VÀ TRÍCH KHẤU HAO TSCĐ "&IF($G$1="All","",RIGHT($G$1,LEN($G$1)-5)&" ")&"NĂM "&YEAR(KB_Den) -> SỔ THEO DÕI VÀ TRÍCH KHẤU HAO TSCĐ NĂM 2026
Q9: Đơn vị tính: đồng Việt Nam
A10: Ký hiệu | B10: Tài khoản | C10: Số TT | D10: Ghi tăng TSCĐ | K10: Khấu hao TSCĐ | O10: Ghi giảm TSCĐ | R10: Không in, không xóa | V10: Chi tiết khấu hao từng tháng
D11: Chứng từ | F11: Tên, đặc điểm, kí hiệu TSCĐ | G11: Nước sản xuất | H11: Tháng năm đưa vào sử dụng | I11: Số hiệu TSCĐ | J11: Nguyên giá TSCĐ | K11: Khấu hao | N11: Khấu hao đã tính đến khi ghi giảm TSCĐ | O11: Chứng từ | Q11: Lý do giảm TSCĐ | R11: Khấu hao cộng dồn đến cuối năm trước | S11: Khấu hao cộng dồn năm nay | T11: Khấu hao tháng | V11: 1 | W11: 2 | X11: 3 | Y11: 4 | Z11: 5 | AA11: 6 | AB11: 7 | AC11: 8 | AD11: 9 | AE11: 10 | AF11: 11 | AG11: 12
D12: Số hiệu | E12: Ngày tháng | K12: Tỷ lệ (%) khấu hao | L12: Thời gian | M12: Mức khấu hao năm | O12: Số hiệu | P12: Ngày, tháng, năm
A15: [0] | B15: [1] | C15: [2] | D15: [3] | E15: [4] | F15: [5] | G15: [6] | H15: [7] | I15: [8] | J15: [9] | K15: [10] | L15: [11] | M15: [12] | N15: [13] | O15: [14] | P15: [15] | Q15: [16] | R15: [17] | S15: [18] | T15: [19] | V15: [1] | W15: [2] | X15: [3] | Y15: [4] | Z15: [5] | AA15: [6] | AB15: [7] | AC15: [8] | AD15: [9] | AE15: [10] | AF15: [11] | AG15: [12]
F18: Tổng cộng TSCĐ
N20: , Ngày 31 tháng 12 năm 2023
E21: Người ghi sổ | I21: Kế toán trưởng | N21: Người đại diện theo pháp luật
E22: (Ký, họ tên) | I22: (Ký, họ tên) | N22: (Ký, họ tên, đóng dấu)
E28: =IF(ISBLANK(KB_TQuy),"",KB_TQuy) | I28: =IF(ISBLANK(KB_KTT),"",KB_KTT) | N28: =KB_GD -> 0

Sheet DK_HHDV
B4: BẢNG THEO DÕI SỐ DƯ ĐẦU KỲ VÀ PHÁT SINH HÀNG HÓA, DỊCH VỤ | K4: BẢNG KÝ HIỆU ĐỊNH KHOẢN
B5: Mã hàng hóa, dịch vụ | C5: Tên hàng hóa, dịch vụ | D5: ĐVT | E5: ="TỒN ĐẦU NĂM "&KB_Nam -> TỒN ĐẦU NĂM 2026 | H5: Định khoản | I5: K.Tra trùng | K5: Tài khoản | L5: Diễn giải
E6: Số lượng | F6: Đơn giá | G6: Thành tiền
B7: [1] | C7: [2] | D7: [3] | E7: [4] | F7: [5] | G7: [6] | H7: [7] | I7: [8] | K7: [1] | L7: [2] | M7: Lưu ý:
K8: All | L8: Hàng hóa, dịch vụ | M8: _ Nhập liên tục không ngắt quãng
K9: 1521 | L9: Nguyên Vật Liệu | M9: _ Phải khai báo ký hiệu định khoản và nội dung diễn giải
K10: 154 | L10: Dở Dang | M10: _ Không cần khai báo tài khoản xuất khác hoặc nhập khác. Nếu muốn nhập khác hoặc xuất thể hiện trên bảng NXT thì khi định khoản bên NK Bán hoặc NK Mua ghép thêm chữ "K"
K11: 155 | L11: Thành Phẩm | M11: _ Luôn bắt đầu bằng tài khoản: 152;153;154;155;156
K12: 1561 | L12: Hàng Hóa | M12: _Tài khoản All luôn có và nằm đầu tiên
K13: 157 | L13: Hàng hóa đang đi đường

Sheet RapMa
M2: Sheet cần ráp mã: | N2: NK_Ban
A4: RÁP MÃ HÀNG HÓA - DỊCH VỤ
A5: Tháng | B5: Chứng từ | D5: Chi tiết chứng từ | J5: Định khoản | K5: Dòng NK | L5: Dò tìm mã hàng trong Danh Mục
B6: Số | C6: Ngày | D6: Mã HH-DV | E6: Tên HH-DV | F6: Đơn vị tính | G6: Số lượng | H6: Đơn giá | I6: Thành tiền | L6: Mã HH-DV | M6: Tên HH-DV | N6: Đơn vị tính | O6: Tin cậy | P6: Gợi ý 2 | Q6: Gợi ý 3
A7: [1] | B7: [2] | C7: [3] | D7: [4] | E7: [5] | F7: [6] | G7: [7] | H7: [8] | I7: [9] | J7: [10] | K7: [11] | L7: [12] | M7: [13] | N7: [14] | O7: [15] | P7: [16] | Q7: [17]

Sheet DM_RapMa
B2: THIẾT LẬP RÁP MÃ
B3: Sửa trực tiếp vào cột «Giá trị». Để trống thì chương trình dùng số mặc định.
B5: Ráp mã tự động | C5: Giá trị | D5: Giải thích
B6: Ngưỡng tự điền mã (%) | C6: 70 | D6: Độ tin cậy tối thiểu để chương trình tự điền mã vào cột «Mã HH-DV»
B7: Cách biệt tối thiểu với ứng viên 2 | C7: 15 | D7: Ứng viên nhất phải hơn ứng viên nhì bấy nhiêu % thì mới tự điền
B8: Kiểu sinh mã mới | C8: 1 | D8: 0 = chỉ lấy tên · 1 = nhóm_tên (NVL_Ong_Nhua_90) · 2 = nhóm + số thứ tự (NVL0001)
B9: Số từ tối đa lấy vào mã | C9: 4 | D9: Cụm chữ số (0.4 · C100 · 30x60) luôn được giữ, không tính vào số từ này
B10: Thêm đơn vị tính vào đuôi mã | C10: 0 | D10: 1 = có (Ton_Lanh_04_Kg) · 0 = không
B11: Bắt buộc trùng cụm số | C11: 1 | D11: 1 = hai tên phải cùng cụm số mới ráp (Nối ray 3P ≠ Ray điện 3P 100A) · 0 = bỏ luật này
B16: TỪ ĐỒNG NGHĨA
B17: Nhà cung cấp viết một kiểu, danh mục của mình viết một kiểu. Ghi vào đây để máy quy về một mối trước khi dò.
B18: Chữ trong nhật ký | C18: Quy về chữ | D18: Ghi chú
B19: TOLE | C19: TON | D19: ví dụ sẵn — xoá được
B20: TOL | C20: TON
B21: BU LONG | C21: BULONG
B220: TỪ KỴ NHAU
B221: Hai chữ này không bao giờ là một mặt hàng — dù máy chấm điểm cao thì cũng không được ráp.
B222: Chữ bên này | C222: Kỵ với chữ | D222: Ghi chú
B223: Chổi điện | C223: Tay lấy điện | D223: chổi than ≠ bộ lấy điện, cùng 3P 60A nên máy hay nhầm

Sheet NXT
D1: Chọn TK kết chuyển: | F1: 1521
B5: ="Đơn vị : "&KB_CTy -> Đơn vị : | F5: ="BẢNG TỔNG HỢP NHẬP XUẤT TỒN "&UPPER(VLOOKUP($F$1,DK_HHDV!$K$8:$L$18,2,0)) -> BẢNG TỔNG HỢP NHẬP XUẤT TỒN NGUYÊN VẬT LIỆU | Y5: BẢNG THEO DÕI GIÁ TRỊ NHẬP - XUẤT
B6: ="Địa chỉ : "&KB_DC -> Địa chỉ : | F6: TỪ THÁNG 1 ĐẾN THÁNG 12 | Y6: TKDK | Z6: Diễn giải | AA6: 1 | AB6: 2 | AC6: 3 | AD6: 4 | AE6: 5 | AF6: 6 | AG6: 7 | AH6: 8 | AI6: 9 | AJ6: 10 | AK6: 11 | AL6: 12
B7: ="Mã số thuế : "&KB_MST -> Mã số thuế : | F7: ="NĂM "& KB_Nam -> NĂM 2026
U9: Đơn vị tính: đồng Việt Nam
B10: Stt | C10: Mã hàng | D10: Tên HH, DV | E10: ĐVT | F10: Tồn đầu kỳ | H10: Nhập trong kỳ | J10: Nhập khác trong kỳ | L10: Nhập trong kỳ | N10: Xuất trong kỳ | P10: Xuất trong kỳ | R10: Xuất trong kỳ | T10: Tồn cuối kỳ | V10: Giá | W10: Định khoản
F11: Số lượng | G11: Thành tiền | H11: Số lượng | I11: Thành tiền | J11: Số lượng | K11: Thành tiền | L11: Số lượng | M11: Thành tiền | N11: Số lượng | O11: Thành tiền | P11: Số lượng | Q11: Thành tiền | R11: Số lượng | S11: Thành tiền | T11: Số lượng | U11: Thành tiền
B12: [1] | C12: [2] | D12: [2] | E12: [3] | F12: [4] | G12: [5] | H12: [7'] | I12: [8'] | J12: [7''] | K12: [8''] | L12: [6] | M12: [7] | N12: [9'] | O12: [10'] | P12: [9''] | Q12: [10''] | R12: [8] | S12: [9] | T12: [10] | U12: [11] | V12: Cuối Kỳ | W12: [0]
D16: Tổng cộng
T18: , Ngày 31 tháng 12 năm 2023
D19: Người ghi sổ | L19: Kế toán trưởng | T19: Người đại diện theo pháp luật
D20: (Ký, họ tên) | L20: (Ký, họ tên) | T20: (Ký, họ tên, đóng dấu)
D26: =IF(ISBLANK(KB_TQuy),"",KB_TQuy) | L26: =IF(ISBLANK(KB_KTT),"",KB_KTT) | T26: =KB_GD -> 0

Sheet GV
T4: VÙNG THEO DÕI VAT - NGƯỜI DÙNG CUNG CẤP SỐ LIỆU ĐỂ KẾT CHUYỂN NHẬT KÝ CHUNG
B5: BẢNG KHAI BÁO SỐ DƯ VÀ TÍNH GIÁ VỐN CUỐI KỲ | U5: BẢNG THEO DÕI THUẾ GTGT ( THEO THÁNG - NGƯỜI DÙNG TỰ K.C ) | AA5: BẢNG THEO DÕI THUẾ GTGT ( THEO QUÝ - NGƯỜI DÙNG TỰ K.C )
T6: Tháng | U6: Đầu Kỳ | V6: Mua Vào | W6: Bán Ra | X6: Cuối Kỳ | Z6: Quý | AA6: Đầu Kỳ | AB6: Mua Vào | AC6: Bán Ra | AD6: Cuối Kỳ
B7: LOẠI HÌNH KINH DOANH THƯƠNG MẠI | U7: [1] | V7: [2] | W7: [3] | X7: [4] | AA7: [1] | AB7: [2] | AC7: [3] | AD7: [4]
B8: Nội dung | C8: Đ.Khoản Nợ | D8: Đ.Khoản Có | E8: 1 | F8: 2 | G8: 3 | H8: 4 | I8: 5 | J8: 6 | K8: 7 | L8: 8 | M8: 9 | N8: 10 | O8: 11 | P8: 12 | T8: {=Thang} -> 1 | Z8: {=Quy} -> I
B9: Giá vốn thương mại | C9: 6321 | D9: 1561 | T9: 2 | Z9: II
B10: Giá vốn thương mại | C10: 6321 | D10: 1562 | T10: 3 | Z10: III
T11: 4 | Z11: IV
T12: 5
B13: LOẠI HÌNH KINH DOANH SẢN XUẤT; XÂY DỰNG - LẮP ĐẶT; DỊCH VỤ … | T13: 6
B14: Nội dung | C14: Đ.Khoản Nợ | D14: Đ.Khoản Có | E14: 1 | F14: 2 | G14: 3 | H14: 4 | I14: 5 | J14: 6 | K14: 7 | L14: 8 | M14: 9 | N14: 10 | O14: 11 | P14: 12 | T14: 7
B15: NVL xuất sản xuất | C15: 621 | D15: 1521 | T15: 8
B16: K/C nguyên vật liệu | C16: 1542 | D16: 621 | T16: 9
B17: K/C nhân công sản xuất | C17: 1542 | D17: 622 | T17: 10
B18: K/C chi phí phân bổ | C18: 1542 | D18: 6273 | T18: 11
B19: K/C chi phí khấu hao | C19: 1542 | D19: 6274 | T19: 12
B20: K/C chi phí mua ngoài | C20: 1542 | D20: 6277
B21: K/C chi phí mua khác | C21: 1542 | D21: 6278
B22: Thành phẩm NK | C22: 1551 | D22: 1542
B23: Thành phẩm XK | C23: 6321 | D23: 1551
B26: CÁC BÚT TOÁN LƯƠNG + BẢO HIỂM + THUẾ TNCN
B27: Nội dung | C27: Đ.Khoản Nợ | D27: Đ.Khoản Có | E27: 1 | F27: 2 | G27: 3 | H27: 4 | I27: 5 | J27: 6 | K27: 7 | L27: 8 | M27: 9 | N27: 10 | O27: 11 | P27: 12
B28: BHXH phải nộp NV sản xuất | C28: 622 | D28: 3383
B29: BHYT phải nộp NV sản xuất | C29: 622 | D29: 3384
B30: BHTN phải nộp NV sản xuất | C30: 622 | D30: 3386
B31: BHXH phải nộp NV bán hàng | C31: 6411 | D31: 3383
B32: BHYT phải nộp NV bán hàng | C32: 6411 | D32: 3384
B33: BHTN phải nộp NV bán hàng | C33: 6411 | D33: 3386
B34: BHXH phải nộp NV văn phòng | C34: 6421 | D34: 3383
B35: BHYT phải nộp NV văn phòng | C35: 6421 | D35: 3384
B36: BHTN phải nộp NV văn phòng | C36: 6421 | D36: 3386
B37: BHXH khấu trừ NLĐ | C37: 3341 | D37: 3383
B38: BHYT khấu trừ NLĐ | C38: 3341 | D38: 3384
B39: BHTN khấu trừ NLĐ | C39: 3341 | D39: 3386
... B48: Chi lương | C48: 3341 | D48: 1111
B50: CÁC BÚT TOÁN GIẢM TRỪ DOANH THU (HBTL-CKTM…)
B51: Nội dung | C51: Đ.Khoản Nợ | D51: Đ.Khoản Có | E51: 1 | F51: 2 | G51: 3 | H51: 4 | I51: 5 | J51: 6 | K51: 7 | L51: 8 | M51: 9 | N51: 10 | O51: 11 | P51: 12
B52: Kết chuyển hàng bán trả lại
C61: BẢNG THEO DÕI CHI PHÍ KHẤU HAO VÀ PHÂN BỔ
B62: Nội dung | C62: Ký hiệu | D62: Đ/Khoản | E62: 1 | F62: 2 | G62: 3 | H62: 4 | I62: 5 | J62: 6 | K62: 7 | L62: 8 | M62: 9 | N62: 10 | O62: 11 | P62: 12
...

Sheet TTNV
D1: Lưu ý: cột nào có dấu (*) thì vui lòng điền đầy đủ
I4: THÔNG TIN LÀM HỢP ĐỒNG LAO ĐỘNG | X4: THÔNG TIN LÀM LƯƠNG | AS4: THÔNG TIN THÁNG LÀM VIỆC | BF4: THÔNG TIN THÁNG ĐÓNG BẢO HIỂM | BS4: BẢNG TỶ LỆ ĐÓNG BH QUA CÁC THÁNG | CB4: Bảng Ký Hiệu Định Khoản
B6: STT | C6: Mã NV (*) | D6: Tên nhân viên (*) | E6: MST TNCN | F6: Số CMND (*) | G6: Ngày cấp (*) | H6: Nơi cấp (*) | I6: Thông tin liên lạc | N6: Thông tin công việc | R6: Thông tin HĐLĐ | X6: Các khoản phụ cấp | AC6: Các khoản phụ cấp không thường xuyên | AG6: Giảm trừ gia cảnh | AK6: Thu nhập miễn thuế TNCN | AN6: Ghi chú | AS6: Tháng làm việc (*) | BF6: Tháng làm việc (*)
I7: Địa chỉ (*) | J7: Đ.Thoại | K7: Fax | L7: Email | M7: Số TK ngân hàng | N7: Công việc (*) | O7: Mô tả công việc (*) | P7: Mức lương (*) | Q7: Mức lương đóng BHXH (*) | R7: Số HĐLĐ (*) | S7: Loại HĐLĐ (*) | T7: Thời gian | V7: Ghi chú lao động NN hay VN (*) | X7: Cơm trưa | Y7: Điện thoại | Z7: Xăng | AA7: Nhà ở | AB7: Khác | AC7: Lễ 30/4 | AD7: Tháng tính PC | AE7: Lễ 2/9 | AF7: Tháng tính PC | AG7: Bản thân | AH7: Người phụ thuộc | AK7: Cơm trưa | AL7: Điện thoại | AM7: Khác | AN7: Định khoản (*) | AO7: Loại (*) | AP7: H.Thức trả lương (*) | AQ7: Ủy quyền QToan (*) | AS7: 1 | AT7: 2 | AU7: 3 | AV7: 4 | AW7: 5 | AX7: 6 | AY7: 7 | AZ7: 8 | BA7: 9 | BB7: 10 | BC7: 11 | BD7: 12 | BF7: 1 | BG7: 2 | BH7: 3 | BI7: 4 | BJ7: 5 | BK7: 6 | BL7: 7 | BM7: 8 | BN7: 9 | BO7: 10 | BP7: 11 | BQ7: 12 | BT7: Việt Nam | BV7: Nước ngoài | BX7: Mức đóng Max | BZ7: Tỷ giá tính lương NN
T8: Bắt đầu | U8: Kết thúc | AH8: Số lượng | AI8: Số tiền | AJ8: Tháng bắt đầu | BS8: Tháng | BT8: Công ty | BU8: Người LĐ | BV8: Công ty | BW8: Người LĐ | BX8: BHXH, BHYT | BY8: BHTN | CB8: K.Hiệu | CC8: Diễn giải
B9: [1] | C9: [2] | D9: [3] | E9: [4] | F9: [5] | G9: [6] | H9: [7] | I9: [8] | J9: [9] | K9: [10] | L9: [11] | M9: [12] | N9: [13] | O9: [14] | P9: [15] | Q9: [16] | R9: [17] | S9: [18] | T9: [19] | U9: [20] | V9: [21] | X9: [PC] | Y9: [PC] | Z9: [PC] | AA9: [PC] | AB9: [PC] | AC9: [KTX] | AD9: [KTX] | AE9: [KTX] | AF9: [KTX] | AG9: [GC] | AH9: [GC] | AI9: [GC] | AJ9: [GC] | AK9: [MT] | AL9: [MT] | AM9: [MT] | AN9: [1] | AO9: [2] | AP9: [3] | AQ9: [4] | AS9: [1] | AT9: [2] | AU9: [3] | AV9: [4] | AW9: [5] | AX9: [6] | AY9: [7] | AZ9: [8] | BA9: [9] | BB9: [10] | BC9: [11] | BD9: [12] | BF9: [1] | BG9: [2] | BH9: [3] | BI9: [4] | BJ9: [5] | BK9: [6] | BL9: [7] | BM9: [8] | BN9: [9] | BO9: [10] | BP9: [11] | BQ9: [12] | BS9: [1] | BT9: [2] | BU9: [3] | BV9: [4] | BW9: [5] | BX9: [6] | BY9: [7] | BZ9: [8] | CB9: [1] | CC9: [2]
BF10: All | BG10: All | BH10: All | BI10: All | BJ10: All | BK10: All | BL10: All | BM10: All | BN10: All | BO10: All | BP10: All | BQ10: All | BS10: {=Thang} -> 1 | BT10: 17.5;3;1 | BU10: 8;1.5;1 | BV10: 3.5;3;0 | BW10: 0;1.5;0 | BX10: =1490000*20 -> 29800000 | BY10: =4420000*20 -> 88400000 | BZ10: 22100 | CB10: 622 | CC10: Nhân công trực tiếp
BS11: 2 | BT11: 17.5;3;1 | BU11: 8;1.5;1 | BV11: 3.5;3;0 | BW11: 0;1.5;0 | BX11: =1490000*20 -> 29800000 | BY11: =4420000*20 -> 88400000 | BZ11: 22100 | CB11: 6271 | CC11: Nhân công sản xuất chung
BS12: 3 | BT12: 17.5;3;1 | BU12: 8;1.5;1 | BV12: 3.5;3;0 | BW12: 0;1.5;0 | BX12: =1490000*20 -> 29800000 | BY12: =4420000*20 -> 88400000 | BZ12: 22100 | CB12: 6411 | CC12: Nhân viên bán hàng
BS13: 4 | BT13: 17.5;3;1 | BU13: 8;1.5;1 | BV13: 3.5;3;0 | BW13: 0;1.5;0 | BX13: =1490000*20 -> 29800000 | BY13: =4420000*20 -> 88400000 | BZ13: 22100 | CB13: 6421 | CC13: Nhân viên văn phòng
BS14: 5 | BT14: 17.5;3;1 | BU14: 8;1.5;1 | BV14: 3.5;3;0 | BW14: 0;1.5;0 | BX14: =1490000*20 -> 29800000 | BY14: =4420000*20 -> 88400000 | BZ14: 22100
BS15: 6 | BT15: 17.5;3;1 | BU15: 8;1.5;1 | BV15: 3.5;3;0 | BW15: 0;1.5;0 | BX15: =1490000*20 -> 29800000 | BY15: =4420000*20 -> 88400000 | BZ15: 22100
BS16: 7 | BT16: 17;3;1 | BU16: 8;1.5;1 | BV16: 3;3;0 | BW16: 0;1.5;0 | BX16: =1490000*20 -> 29800000 | BY16: =4420000*20 -> 88400000 | BZ16: 22100
BS17: 8 | BT17: 17;3;1 | BU17: 8;1.5;1 | BV17: 3;3;0 | BW17: 0;1.5;0 | BX17: =1490000*20 -> 29800000 | BY17: =4420000*20 -> 88400000 | BZ17: 22100
BS18: 9 | BT18: 17;3;1 | BU18: 8;1.5;1 | BV18: 3;3;0 | BW18: 0;1.5;0 | BX18: =1490000*20 -> 29800000 | BY18: =4420000*20 -> 88400000 | BZ18: 22100
BS19: 10 | BT19: 17;3;0 | BU19: 8;1.5;1 | BV19: 3;3;0 | BW19: 0;1.5;0 | BX19: =1490000*20 -> 29800000 | BY19: =4420000*20 -> 88400000 | BZ19: 22100
BS20: 11 | BT20: 17;3;0 | BU20: 8;1.5;1 | BV20: 3;3;0 | BW20: 0;1.5;0 | BX20: =1490000*20 -> 29800000 | BY20: =4420000*20 -> 88400000 | BZ20: 22100
BS21: 12 | BT21: 17;3;0 | BU21: 8;1.5;1 | BV21: 3;3;0 | BW21: 0;1.5;0 | BX21: =1490000*20 -> 29800000 | BY21: =4420000*20 -> 88400000 | BZ21: 22100

Sheet HDLD
Q1: Mã nhân viên: | R1: NVA
F5: =UPPER(KB_CTy) | N5: CỘNG HÒA XÃ HỘI CHỦ NGHĨA VIỆT NAM
N6: Độc lập - Tự do - Hạnh phúc
F8: Số HĐLĐ: | P8: , ngày 30 tháng 12 năm 1899
G10: HỢP ĐỒNG LAO ĐỘNG
G12: Căn cứ Bộ luật Lao động số 10/2012/QH13 ngày 18 tháng 6 năm 2012;
G13: Căn cứ Nghị định số 05/2015/NĐ-CP ngày 12 tháng 01 năm 2015 quy định chi tiết và hướng dẫn thi hành một số nội dung của Bộ Luật lao động;
G15: ="Căn cứ nhu cầu hoạt động của "&KB_CTy&" và xét khả năng của người lao động;" -> Căn cứ nhu cầu hoạt động của và xét khả năng của người lao động;
F17: Hợp đồng lao động (“HĐLĐ”) này được ký ngày 30 tháng 12 năm 1899 tại Văn phòng DD, địa chỉ , bởi và giữa các bên có đầy đủ tư cách giao kết hợp đồng lao động theo quy định, gồm:
F20: Thông tin | H20: BÊN SỬ DỤNG LAO ĐỘNG (Sau đây gọi là Doanh nghiệp) | M20: NGƯỜI LAO ĐỘNG (Sau đây gọi là NLĐ)
F21: Tên chính thức | H21: =KB_CTy -> 0 | M21: Nhân Viên A
F22: Mã số thuế/CMND | H22: ="Mã số thuế: "&KB_MST -> Mã số thuế: | M22: Số CMND:
E23: Điền chi tiết ngày cấp (nếu muốn) | H23: Ngày cấp: | M23: Ngày cấp:
E24: Điền chi tiết nơi cấp (nếu muốn) | H24: Nơi cấp: | M24: Nơi cấp:
F25: Thông tin liên lạc | H25: ="Điện thoại: "&KB_DT -> Điện thoại: | M25: Điện thoại:
H26: ="Fax: "&KB_Fax -> Fax: | M26: Fax:
H27: ="Email: "&KB_Email -> Email: | M27: Email:
F28: Địa chỉ | H28: =KB_DC -> 0
F29: Người đại diện | H29: =KB_GD -> 0
E30: Điền chi tiết số TKNH (nếu muốn) | F30: TK ngân hàng
F32: Tùy ngữ cảnh cụ thể, mỗi bên được gọi riêng là “Bên” và hai bên được gọi chung là “Các bên”.
F33: Xét rằng:
G34: - Doanh nghiệp có nhu cầu tuyển dụng và sử dụng lao động phục vụ hoạt động sản xuất kinh doanh; và
G35: - NLĐ là cá nhân độc lập, tự thấy rằng có đầy đủ năng lực giao kết hợp đồng lao động và có thể đáp ứng yêu cầu công việc của Doanh nghiệp.
F37: Sau khi bàn bạc thống nhất, các bên đồng ý ký kết Hợp đồng này với các điều khoản và điều kiện cụ thể như sau:
F38: ĐIỀU 1: CÔNG VIỆC VÀ ĐỊA ĐIỂM LÀM VIỆC
F39: 1.1 Công việc:
G40: Mô tả công viêc:
G41: Doanh nghiệp được quyền tạm thời chuyển NLĐ làm công việc khác so với HĐLĐ trong các trường hợp sau:
H42: a. Thiên tai, hỏa hoạn, dịch bệnh;
H43: b. Áp dụng biện pháp ngăn ngừa, khắc phục tai nạn lao động, bệnh nghề nghiệp;
H44: c. Sự cố điện, nước;
H45: d. Do nhu cầu sản xuất, kinh doanh.
G46: Trường hợp NLĐ không chấp nhận thực hiện việc mới sau điều chuyển thì hai bên tiến hành thanh lý hợp đồng trên cơ sở đồng thuận, nhưng Doanh nghiệp đảm bảo phải trả ít nhất 01 tháng lương do thay đổi công việc dẫn đến chấm dứt hợp đồng trước hạn.
F49: 1.2 Địa điểm làm việc của người lao động:
G50: ="Tại trụ sở chính của Doanh nghiệp, địa chỉ: "&KB_DC&", "&KB_TTP&"." -> Tại trụ sở chính của Doanh nghiệp, địa chỉ: , .
G51: Trường hợp Doanh nghiệp có thay đổi địa chỉ trụ sở chính thì NLĐ tiếp tục làm việc theo địa chỉ mới. Trường hợp đặc biệt theo quyết định của Giám đốc Doanh nghiệp, Doanh nghiệp có thể chỉ định NLĐ làm việc tại địa điểm khác địa chỉ nêu trên nhưng phải báo trước ít nhất 03 ngày để NLĐ kịp thời chuẩn bị.
F55: ĐIỀU 2: THỜI HẠN CỦA HỢP ĐỒNG LAO ĐỘNG
F56: Thời hạn của HĐLĐ này được quy định như sau (đánh dấu X vào  tương ứng với loại HĐLĐ mà Doanh nghiệp giao kết với NLĐ tại phần đầu hợp đồng này):
G58: Loại Hợp đồng giao kết | J58: Thời gian thực hiện hợp đồng | L58: Thời điểm bắt đầu | O58: Thời điểm kết thúc
...

Sheet BangLuong
G1: Phụ cấp nào không có thì bạn ẩn đi, nếu nhiều hơn 5 khoản thì các phụ cấp đó sẽ dồn vào cột phụ cấp khác
G2: Phụ cấp không thường xuyên nào không có thì bạn ẩn đi, nếu quá 2 khoản thì khoản thứ 3 trở đi sẽ cộng dồn vào cột Phụ cấp không thường xuyên khác
B5: ="Đơn vị : "&KB_CTy -> Đơn vị :
B6: ="Địa chỉ : "&KB_DC&", "&KB_TTP -> Địa chỉ : ,
B7: ="Mã số thuế : "&KB_MST -> Mã số thuế :
B8: BẢNG LƯƠNG
B9: TỪ THÁNG 1 ĐẾN THÁNG 12
B10: ="Năm "&KB_Nam -> Năm 2026
U11: Đơn vị tính: đồng Việt Nam
B12: Stt | C12: Họ & Tên | D12: Chức vụ | E12: Lương cơ bản | F12: Phụ cấp ăn trưa | G12: Phụ cấp điện thoại | H12: Phụ cấp xăng | I12: Phụ cấp -1 | J12: Phụ cấp -2 | K12: Phụ cấp khác | L12: Phụ cấp không thường xuyên 1 | M12: Phụ cấp không thường xuyên 2 | N12: Phụ cấp không thường xuyên khác | O12: Tổng Thu Nhập | P12: Các khoản trừ | S12: Thực lãnh | T12: Ký nhận | U12: Ghi chú | V12: Không in, không xóa
P13: Bảo hiểm | Q13: TNCN | R13: Khác | V13: Mã số thuế | W13: Số CMND
B16: [1] | C16: [2] | D16: [3] | E16: [4] | F16: [5] | G16: [6] | H16: [7] | I16: [8] | J16: [9] | K16: [10] | L16: [11] | M16: [12] | N16: [13] | O16: [14] | P16: [15] | Q16: [16] | R16: [17] | S16: [18] | T16: [19] | U16: [20] | V16: [21] | W16: [22]
C19: Tổng cộng
S21: , ngày 31 tháng 12 năm 2023
C22: Người lập biểu | S22: Người đại diện theo pháp luật
C23: (Ký, họ tên) | S23: (Ký, họ tên, đóng dấu)
C29: =IF(ISBLANK(KB_TQuy),"",KB_TQuy) | S29: =KB_GD -> 0

Sheet TinhLuong
I1: Phụ cấp nào không có thì bạn ẩn đi, nếu nhiều hơn 5 khoản thì các phụ cấp đó sẽ dồn vào cột phụ cấp khác
I2: Phụ cấp không thường xuyên nào không có thì bạn ẩn đi, nếu quá 2 khoản thì khoản thứ 3 trở đi sẽ cộng dồn vào cột Phụ cấp không thường xuyên khác
A4: BẢNG TÍNH LƯƠNG | AB4: VÙNG TÍNH BẢO HIỂM VÀ THUẾ THU NHẬP CÁ NHÂN
A6: Mã nhân viên | B6: Họ & Tên | C6: Mã số thuế TNCN | D6: Số chứng minh nhân dân | E6: Chức vụ | F6: Lương tính BHXH | G6: Lương cơ bản | H6: Phụ cấp ăn trưa | I6: Phụ cấp điện thoại | J6: Phụ cấp xăng | K6: Phụ cấp nhà ở | L6: Phụ cấp -2 | M6: Phụ cấp khác | N6: Phụ cấp không thường xuyên 1 | O6: Phụ cấp không thường xuyên 2 | P6: Phụ cấp không thường xuyên khác | Q6: Tổng Thu Nhập | R6: Các khoản trừ | U6: Thực lãnh | V6: Định khoản | W6: Loại HĐLĐ | X6: Hình thức trả lương | Y6: Tháng | AB6: Vùng tính bảo hiểm | AH6: Vùng tính thuế TNCN | AP6: Tổng TNCT trả cho cá nhân thuộc diện khấu trừ thuế | AQ6: Ủy quyền quyết toán thuế TNCN | AR6: Vùng công đoàn
R7: Bảo hiểm | S7: TNCN | T7: Khác | AB7: Bảo hiểm xã hội | AD7: Bảo hiểm y tế | AF7: Bảo hiểm thất nghiệp | AH7: TN chịu thuế | AI7: Các khoản giảm trừ | AN7: TN tính thuế | AO7: Thuế TNCN | AR7: Kinh phí công đoàn | AS7: Đoàn phí
AI8: Bảo hiểm bắt buộc | AJ8: Giảm trừ gia cảnh | AM8: Khác | AR8: 0.02 | AS8: 0.01
AB9: Công ty | AC9: NLĐ | AD9: Công ty | AE9: NLĐ | AF9: Công ty | AG9: NLĐ | AJ9: Bản thân | AK9: Người phụ thuộc | AR9: Công ty | AS9: NLĐ
A10: [1] | B10: [2] | C10: [3] | D10: [4] | E10: [5] | F10: [6] | G10: [7] | H10: [8] | I10: [9] | J10: [10] | K10: [11] | L10: [12] | M10: [13] | N10: [14] | O10: [15] | P10: [16] | Q10: [17] | R10: [18] | S10: [19] | T10: [20] | U10: [21] | V10: [22] | W10: [23] | X10: [24] | Y10: [25] | AK10: Số lg | AL10: Số tiền

Sheet CDSPS
A1: 1
A2: 9
C5: ="Đơn vị : "&KB_CTy -> Đơn vị : | H5: Mẫu số S06 – DN
C6: ="Địa chỉ : "&KB_DC -> Địa chỉ : | H6: (Kèm theo Thông tư số 99/2025/TT-BTC
C7: ="Mã số thuế : "&KB_MST -> Mã số thuế : | H7: Ngày 27/10/2025 của Bộ trưởng Bộ Tài chính)
C8: BẢNG CÂN ĐỐI SỐ PHÁT SINH
E9: TỪ THÁNG 1 | F9: ĐẾN THÁNG 9
E10: NĂM | F10: 2026
J11: Đơn vị tính: đồng Việt Nam
C12: Số hiệu tài khoản | D12: Tên tài khoản kế toán | E12: Số dư đầu kỳ | G12: Số phát sinh trong kỳ | I12: Số dư cuối kỳ
E13: Nợ | F13: Có | G13: Nợ | H13: Có | I13: Nợ | J13: Có | K13: K.In
C14: [1] | D14: [2] | E14: [3] | F14: [4] | G14: [5] | H14: [6] | I14: [7] | J14: [8] | K14: K.Xóa
C15: 111 | D15: TIỀN MẶT | E15: 0 | F15: 0 | G15: 0 | H15: 0 | I15: 0 | J15: 0 | K15: 0
C16: 1111 | D16: Tiền Việt Nam | E16: 0 | F16: 0 | G16: 0 | H16: 0 | I16: 0 | J16: 0 | K16: 0
C17: 1112 | D17: Ngoại tệ | E17: 0 | F17: 0 | G17: 0 | H17: 0 | I17: 0 | J17: 0 | K17: 0
C18: 1113 | D18: Vàng tiền tệ | E18: 0 | F18: 0 | G18: 0 | H18: 0 | I18: 0 | J18: 0 | K18: 0
C19: 112 | D19: TIỀN GỬI KHÔNG KỲ HẠN | E19: 0 | F19: 0 | G19: 0 | H19: 0 | I19: 0 | J19: 0 | K19: 0
C20: 1121 | D20: Tiền gửi không kỳ hạn Việt Nam | E20: 0 | F20: 0 | G20: 0 | H20: 0 | I20: 0 | J20: 0 | K20: 0
C21: 1121-01 | D21: Tiền gữi không kỳ hạn Việt Nam Đồng | E21: 0 | F21: 0 | G21: 0 | H21: 0 | I21: 0 | J21: 0 | K21: 0
C22: 1121-02 | D22: Tiền gữi không kỳ hạn Việt Nam Đồng | E22: 0 | F22: 0 | G22: 0 | H22: 0 | I22: 0 | J22: 0 | K22: 0
C23: 1121-03 | D23: Tiền gữi không kỳ hạn Việt Nam Đồng | E23: 0 | F23: 0 | G23: 0 | H23: 0 | I23: 0 | J23: 0 | K23: 0
C24: 1121-04 | D24: Tiền gữi không kỳ hạn Việt Nam Đồng | E24: 0 | F24: 0 | G24: 0 | H24: 0 | I24: 0 | J24: 0 | K24: 0
C25: 1121-05 | D25: Tiền gữi không kỳ hạn Việt Nam Đồng | E25: 0 | F25: 0 | G25: 0 | H25: 0 | I25: 0 | J25: 0 | K25: 0
C26: 1121-06 | D26: Tiền gữi không kỳ hạn Việt Nam Đồng | E26: 0 | F26: 0 | G26: 0 | H26: 0 | I26: 0 | J26: 0 | K26: 0
